Workbook

Sheet Diario
B7: COMENTARIOS DEL DIA
B9: * Temperatura máxima en Buenos Aires aumentando a 30°C hacia el fin de semana y lunes 16/03.
B10: * Demanda Total del sistema ubicándose en 125 MMm3/día.
B11: * Consumo de Cammesa en 53 MMm3 para hoy y mañana. Proyecta disminuir consumo hacia el domingo. A rever si ajustan.
B12: * Linepacks de Transportistas con buen stock. TGS alcanzado el limite superior.
B13: * La Calera: continuan trabajos de matenimiento en compresores. Iny. máxima de 13,5/13,7 MMm3.
B14: * TGN: informa restricción de capacidad de transporte en el Centro Oeste, limitando el flujo de gas hacia el Norte, impactando en la Exportación Int.
B16: SISTEMA TGS | G16: SISTEMA TGN | L16: INYECCION DE GNL
B17: Día | C17: Lineapack [MMm3] | D17: Var [MMm3] | E17: Estado del Sistema | G17: Día | H17: Lineapack TGN [MMm3] | I17: Var [MMm3] | J17: Estado del Sistema | L17: Día | M17: Inyección GNL [MMm3] | N17: Stock GNL [MMm3]
B18: =+TODAY()-1 -> 46123 | C18: =+VLOOKUP(B18,'Conv. valores'!$B$8:$V$25,14) -> 235.81 | E18: =+VLOOKUP(B18,Datos!$A$6:$AO$8260,36) -> ALERTA | G18: =+B18 -> 46123 | H18: =+VLOOKUP(G18,'Conv. valores'!$B$8:$V$25,18) -> 134.07248 | J18: =+VLOOKUP(G18,Datos!$A$6:$AO$8260,41) -> NORMAL | L18: =+G18 -> 46123 | M18: =+VLOOKUP(L18,Datos!$A$6:$T$260,19) -> 0 | N18: =+VLOOKUP(L18,Datos!$A$5:$AV$860,48) -> 0
B19: =+TODAY() -> 46124 | C19: =+VLOOKUP(B19,'Conv. valores'!$B$8:$V$25,14) -> 0 | D19: =+C19-C18 -> -235.81 | E19: =+VLOOKUP(B19,Datos!$A$6:$AO$8260,36) -> ALERTA | G19: =+TODAY() -> 46124 | H19: =+VLOOKUP(G19,'Conv. valores'!$B$8:$V$25,18) -> 0 | I19: =+H19-H18 -> -134.07248 | J19: =+VLOOKUP(G19,Datos!$A$6:$AO$8260,41) -> NORMAL | L19: =+TODAY() -> 46124 | M19: =+VLOOKUP(L19,Datos!$A$6:$T$260,19) -> 0 | N19: =+VLOOKUP(L19,Datos!$A$5:$AV$860,48) -> 0
B20: =+TODAY()+1 -> 46125 | C20: =+VLOOKUP(B20,'Conv. valores'!$B$8:$V$25,14) -> 0 | D20: =+C20-C19 -> 0 | E20: =+VLOOKUP(B20,Datos!$A$6:$AO$8260,36) -> NORMAL | G20: =+TODAY()+1 -> 46125 | H20: =+VLOOKUP(G20,'Conv. valores'!$B$8:$V$25,18) -> 0 | I20: =+H20-H19 -> 0 | J20: =+VLOOKUP(G20,Datos!$A$6:$AO$8260,41) -> NORMAL | L20: =+TODAY()+1 -> 46125 | M20: =+VLOOKUP(L20,Datos!$A$6:$T$260,19) -> 0 | N20: =+N19-M20 -> 0
B21: Lim. Sup: 235; Lim. Inf: 215 | G21: Lim. Sup: 142; Lim. Inf: 110
B23: Afectación de Transporte (corte en MMm3)
H24: Capacidad MMm3
B25: GAS ANDES | G25: TGN Y TGS | H25: 33.7 | I25: 37.2
B26: FECHA | C26: Gas Andes | D26: Impac. PPSA | G26: FECHA | H26: CCO | I26: TGS NQN
B27: =+TODAY() -> 46124 | C27: =+VLOOKUP(B27,Datos!$CC$77:$CI$260,2)-8.5 -> 0 | D27: =+C27/-8.5 -> 0 | G27: 46006 | H27: =+VLOOKUP(B27,Datos!$CC$77:$CI$260,4) -> 0 | I27: =+VLOOKUP(B27,Datos!$CC$77:$CI$260,6) -> -0.5
B28: =+B27+1 -> 46125 | C28: =+VLOOKUP(B28,Datos!$CC$77:$CI$260,2)-8.5 -> 0 | D28: =+C28/-8.5 -> 0 | G28: =+G27+1 -> 46007 | H28: =+VLOOKUP(B28,Datos!$CC$77:$CI$260,4) -> 0 | I28: =+VLOOKUP(B28,Datos!$CC$77:$CI$260,6) -> -0.5

Sheet Proyección Semanal
B7: COMENTARIOS DE LA SEMANA
B9: * Inicio de semana con Temp. Máxima de 34° C., bajando hacia el fin de semana con promedios de 24 °C.
B10: * Demanda Total del sistema inicia la semana con 130 MMm3/día y disminuye con el correr de los dias ante un menor consumo de generación.
B11: * Consumo de gas de Cammesa inicia en 60 MMm3 y disminuye a los 45 MMm3 para el fin de semana largo.
B12: * Linepacks de Transportistas con buen stock, incrementando hacia el fin de semana.
B13: * Mantenimiento TGN: 17 al 20 y 23/3 trabajos en PC Chajan, scrapper en tramo Villa Mercedes-Bulnes con afectación promedio de 4MMm3/d en tramos finales.
B14: * La Calera: inyectando un promedio de 14 MMm3 por día.
B15: * Loma Negra: miércoles 18/03 se cumplen los 10 días de parada programada.
B17: SISTEMA TGS | G17: SISTEMA TGN | L17: INYECCION DE GNL
B18: Día | C18: Lineapack [MMm3] | D18: Var [MMm3] | E18: Estado del Sistema | G18: Día | H18: Lineapack TGN [MMm3] | I18: Var [MMm3] | J18: Estado del Sistema | L18: Día | M18: Inyección GNL [MMm3] | N18: Stock GNL [MMm3]
B19: =+TODAY()-3 -> 46121 | C19: =+VLOOKUP(B19,'Conv. valores'!$B$8:$V$25,14) -> 226.87 | D19: =+C19-VLOOKUP(TODAY()-4,'Conv. valores'!B8:V25,14) -> -1.63 | E19: =+VLOOKUP(B19,Datos!$A$6:$AO$860,36) -> NORMAL | G19: =+TODAY()-3 -> 46121 | H19: =+VLOOKUP(G19,'Conv. valores'!$B$8:$V$25,18) -> 130.63668 | I19: =+H19-VLOOKUP(TODAY()-4,'Conv. valores'!B8:V25,18) -> 3.50479 | J19: =+VLOOKUP(G19,Datos!$A$6:$AO$860,41) -> NORMAL | L19: =+TODAY()-3 -> 46121 | M19: =+VLOOKUP(L19,Datos!$A$6:$T$2600,19) -> 0 | N19: =+VLOOKUP(L19,Datos!$A$5:$AV$860,48) -> 0
B20: =+TODAY()-2 -> 46122 | C20: =+VLOOKUP(B20,'Conv. valores'!$B$8:$V$25,14) -> 229.32 | D20: =+C20-C19 -> 2.45 | E20: =+VLOOKUP(B20,Datos!$A$6:$AO$860,36) -> ALERTA | G20: =+TODAY()-2 -> 46122 | H20: =+VLOOKUP(G20,'Conv. valores'!$B$8:$V$25,18) -> 130.55521 | I20: =+H20-H19 -> -0.08147 | J20: =+VLOOKUP(G20,Datos!$A$6:$AO$860,41) -> NORMAL | L20: =+TODAY()-2 -> 46122 | M20: =+VLOOKUP(L20,Datos!$A$6:$T$2600,19) -> 0 | N20: =+VLOOKUP(L20,Datos!$A$5:$AV$860,48) -> 0
B21: =+TODAY()-1 -> 46123 | C21: =+VLOOKUP(B21,'Conv. valores'!$B$8:$V$25,14) -> 235.81 | D21: =+C21-C20 -> 6.49 | E21: =+VLOOKUP(B21,Datos!$A$6:$AO$860,36) -> ALERTA | G21: =+TODAY()-1 -> 46123 | H21: =+VLOOKUP(G21,'Conv. valores'!$B$8:$V$25,18) -> 134.07248 | I21: =+H21-H20 -> 3.51727 | J21: =+VLOOKUP(G21,Datos!$A$6:$AO$860,41) -> NORMAL | L21: =+TODAY()-1 -> 46123 | M21: =+VLOOKUP(L21,Datos!$A$6:$T$2600,19) -> 0 | N21: =+VLOOKUP(L21,Datos!$A$5:$AV$860,48) -> 0
B22: =+TODAY() -> 46124 | C22: =+VLOOKUP(B22,'Conv. valores'!$B$8:$V$25,14) -> 0 | D22: =+C22-C21 -> -235.81 | E22: =+VLOOKUP(B22,Datos!$A$6:$AO$860,36) -> ALERTA | G22: =+TODAY() -> 46124 | H22: =+VLOOKUP(G22,'Conv. valores'!$B$8:$V$25,18) -> 0 | I22: =+H22-H21 -> -134.07248 | J22: =+VLOOKUP(G22,Datos!$A$6:$AO$860,41) -> NORMAL | L22: =+TODAY() -> 46124 | M22: =+VLOOKUP(L22,Datos!$A$6:$T$2600,19) -> 0 | N22: =+VLOOKUP(L22,Datos!$A$5:$AV$860,48) -> 0
B23: Lim. Sup: 235; Lim. Inf: 215 | G23: Lim. Sup: 142; Lim. Inf: 110
B25: Afectación de Transporte (corte en MMm3) | H25: Capacidad MMm3
B26: GAS ANDES | G26: TGN Y TGS | H26: 33.7 | I26: 37.2
B27: FECHA | C27: Gas Andes | D27: Impac. PPSA | G27: FECHA | H27: CCO | I27: TGS NQN
B28: =+'Conv. valores'!B17 -> 46125 | C28: =+VLOOKUP(B28,Datos!$CC$77:$CI$660,2)-8.5 -> -8.5 | D28: =+C28/-8.5 -> 1 | G28: =+B28 -> 46125 | H28: =+VLOOKUP(B28,Datos!$CC$77:$CI$660,4) -> 0 | I28: =+VLOOKUP(B28,Datos!$CC$77:$CI$260,6) -> -0.5
B29: =+B28+1 -> 46126 | C29: =+VLOOKUP(B29,Datos!$CC$77:$CI$660,2)-8.5 -> -8.5 | D29: =+C29/-8.5 -> 1 | G29: =+G28+1 -> 46126 | H29: =+VLOOKUP(B29,Datos!$CC$77:$CI$660,4) -> 0 | I29: =+VLOOKUP(B29,Datos!$CC$77:$CI$260,6) -> -0.5
B30: =+B29+1 -> 46127 | C30: =+VLOOKUP(B30,Datos!$CC$77:$CI$660,2)-8.5 -> -8.5 | D30: =+C30/-8.5 -> 1 | G30: =+G29+1 -> 46127 | H30: =+VLOOKUP(B30,Datos!$CC$77:$CI$660,4) -> 0 | I30: =+VLOOKUP(B30,Datos!$CC$77:$CI$260,6) -> -0.5
B31: =+B30+1 -> 46128 | C31: =+VLOOKUP(B31,Datos!$CC$77:$CI$660,2)-8.5 -> -8.5 | D31: =+C31/-8.5 -> 1 | G31: =+G30+1 -> 46128 | H31: =+VLOOKUP(B31,Datos!$CC$77:$CI$660,4) -> 0 | I31: =+VLOOKUP(B31,Datos!$CC$77:$CI$260,6) -> -0.5 | AL31: *Comparación semanal
B32: =+B31+1 -> 46129 | C32: =+VLOOKUP(B32,Datos!$CC$77:$CI$660,2)-8.5 -> -8.5 | D32: =+C32/-8.5 -> 1 | G32: =+G31+1 -> 46129 | H32: =+VLOOKUP(B32,Datos!$CC$77:$CI$660,4) -> 0 | I32: =+VLOOKUP(B32,Datos!$CC$77:$CI$260,6) -> -0.5 | AL32: FECHA | AM32: T °C | AN32: Dem. Prior. [MMm3]
B33: =+B32+1 -> 46130 | C33: =+VLOOKUP(B33,Datos!$CC$77:$CI$660,2)-8.5 -> -8.5 | D33: =+C33/-8.5 -> 1 | G33: =+G32+1 -> 46130 | H33: =+VLOOKUP(B33,Datos!$CC$77:$CI$660,4) -> 0 | I33: =+VLOOKUP(B33,Datos!$CC$77:$CI$260,6) -> -0.5 | AL33: Semana N-1 | AM33: =+Hoja1!N11 -> 19.571429 | AN33: =+Hoja1!O11 -> 22.514286
B34: =+B33+1 -> 46131 | C34: =+VLOOKUP(B34,Datos!$CC$77:$CI$660,2)-8.5 -> -8.5 | D34: =+C34/-8.5 -> 1 | G34: =+G33+1 -> 46131 | H34: =+VLOOKUP(B34,Datos!$CC$77:$CI$660,4) -> 0 | I34: =+VLOOKUP(B34,Datos!$CC$77:$CI$260,6) -> -0.5 | AL34: Semana N | AM34: =+Hoja1!N12 -> 17.571429 | AN34: =+Hoja1!O12 -> 25.313265
B35: =+B34+1 -> 46132 | C35: =+VLOOKUP(B35,Datos!$CC$77:$CI$660,2)-8.5 -> -8.5 | D35: =+C35/-8.5 -> 1 | G35: =+G34+1 -> 46132 | H35: =+VLOOKUP(B35,Datos!$CC$77:$CI$660,4) -> 0 | I35: =+VLOOKUP(B35,Datos!$CC$77:$CI$260,6) -> -0.5 | AL35: Δ (Delta) | AM35: =+Hoja1!N13 -> -2 | AN35: =+Hoja1!O13 -> 2.7989796
AL36: ΔT/ΔDem Prio | AM36: =+AM35/AN35 -> -0.71454612
W74: S
AN99: * Comparación Diaria. Incluye datos desde Junio 2025.
AN100: * ΔT/ΔDem Prioritaria promedio de -0,4.

Sheet Datos
B1: y = -0,1851x + 24,373 | D1: y = -0,2089x + 29,03 | V1: https://www.tiempo3.com/south-america/argentina/tucuman/san-miguel-de-tucuman?page=past-weather#day=3&month=5 | BT1: 70
B2: https://www.enargas.gob.ar/secciones/transporte-y-distribucion/dod-proyeccion-semanal.php | V2: https://www.meteored.com.ar/
B3: INYECCIONES ENARGAS | V3: TEMPERATURA
H4: Inyección TGS | M4: Inyección TGN | Q4: Inyección Enarsa | V4: Tucumán | Y4: Buenos Aires | AB4: Esquel - CHU | AF4: Linepack TGS | AK4: Linepack TGN | AP4: TRAMOS FINALES | CD4: Gas Andes | CE4: CCO | CG4: TGS NQN | CK4: INYECCIONES EN TGN
A5: Fecha | B5: Demanda DS | C5: Prioritaria | D5: Industria | E5: Usinas | F5: Exportaciones | H5: Sur | I5: NBA I | J5: NBA II | K5: TGS | M5: Norte | N5: Nqn | O5: TGN | Q5: GPM | R5: BOLIVIA | S5: ESCOBAR | T5: ENARSA | V5: Min | W5: Max | X5: Promedio | Y5: Min | Z5: Max | AA5: Promedio | AB5: Min | AC5: Max | AD5: Promedio | AF5: Linepack TGS | AG5: Variación | AH5: Lim Inf. | AI5: Lim. Sup. | AJ5: Sistema | AK5: Linepack TGN | AL5: Variación | AM5: Lim Inf. | AN5: Lim. Sup. | AO5: Sistema | AP5: TGS | AQ5: Lim. Inf. | AR5: Lim Sup | AS5: TGN | AT5: Lim. Inf. | AU5: Lim Sup | AV5: Stock GNL | AW5: Impo Bolivia | BM5: GAS | BN5: GASOIL | BO5: FUELOIL | BP5: CARBON | CD5: Autorización | CE5: Capacidad | CF5: Corte | CG5: Capacidad | CH5: Corte | CI5: Productores | CK5: NQN TGN | CL5: NOA | CM5: ESCOBAR/NORA | CN5: MECA | CO5: ANILLO GBA | CP5: NQN TGS | CQ5: SUR | CR5: 1002 | CS5: 1001 | CT5: 10.01 | CV5: NQN TGS
A6: 45768 | B6: 120.3 | C6: 36.5 | D6: 32.6 | E6: 38.3 | F6: 5 | H6: 28.2 | I6: 10.5 | J6: 31.2 | K6: =SUM(H6:J6) -> 69.9 | M6: 2.7 | N6: 30.3 | O6: =SUM(M6:N6) -> 33 | Q6: 22.7 | R6: 0 | S6: 0 | T6: =SUM(Q6:S6) -> 22.7 | V6: 0 | W6: 0 | X6: =+AVERAGE(V6:W6) -> 0 | Y6: 0 | Z6: 0 | AA6: =+AVERAGE(Y6:Z6) -> 0 | AB6: 0 | AC6: 0 | AD6: =+AVERAGE(AB6:AC6) -> 0 | AF6: 217.12 | AH6: 215 | AI6: 235 | AJ6: NORMAL | AK6: 124.69333 | AO6: NORMAL | AQ6: 73 | AR6: 84 | AT6: 12 | AU6: 17 | BL6: =+A6 -> 45768 | BR6: =+TEXT(BS6,"dddd") -> lunes | BS6: =+BL6 -> 45768 | BT6: =BM6/1000 -> 0 | BU6: =BN6*$CA$9/$CA$8/1000 -> 0 | BV6: =BO6*$CA$10/$CA$8/1000 -> 0 | BW6: =BP6*$CA$11/$CA$8/1000 -> 0 | BX6: =+BT6+BU6+BV6+BW6 -> 0 | BZ6: Poderes calóricos de referencia | CC6: =+BL6 -> 45768
A7: 45769 | B7: 120.6 | C7: 34.3 | D7: 31.1 | E7: 37.8 | F7: 5.1 | H7: 28.1 | I7: 10.4 | J7: 29.9 | K7: =SUM(H7:J7) -> 68.4 | M7: 2.6 | N7: 29.5 | O7: =SUM(M7:N7) -> 32.1 | Q7: 22.3 | R7: 0 | S7: 0 | T7: =SUM(Q7:S7) -> 22.3 | AF7: 220.42 | AG7: =+AF7-AF6 -> 3.3 | AH7: 215 | AI7: 235 | AJ7: NORMAL | AK7: 123.50991 | AL7: =+AK7-AK6 -> -1.183422 | AM7: 110 | AN7: 142 | AO7: NORMAL | AQ7: 73 | AR7: 84 | AT7: 12 | AU7: 17 | BL7: =+A7 -> 45769 | BR7: =+TEXT(BS7,"dddd") -> martes | BS7: =+BL7 -> 45769 | BT7: =BM7/1000 -> 0 | BU7: =BN7*$CA$9/$CA$8/1000 -> 0 | BV7: =BO7*$CA$10/$CA$8/1000 -> 0 | BW7: =BP7*$CA$11/$CA$8/1000 -> 0 | BX7: =+BT7+BU7+BV7+BW7 -> 0 | CC7: =+BL7 -> 45769
A8: 45770 | B8: 118.5 | C8: 30.6 | D8: 32.7 | E8: 41.2 | F8: 5 | H8: 27.5 | I8: 10.2 | J8: 27.8 | K8: =SUM(H8:J8) -> 65.5 | M8: 2.6 | N8: 28.2 | O8: =SUM(M8:N8) -> 30.8 | Q8: 23.1 | R8: 0 | S8: 0 | T8: =SUM(Q8:S8) -> 23.1 | AF8: 222.68 | AG8: =+AF8-AF7 -> 2.26 | AH8: 215 | AI8: 235 | AJ8: NORMAL | AK8: 122.19084 | AL8: =+AK8-AK7 -> -1.319068 | AM8: 110 | AN8: 142 | AO8: NORMAL | AQ8: 73 | AR8: 84 | AT8: 12 | AU8: 17 | BL8: =+A8 -> 45770 | BR8: =+TEXT(BS8,"dddd") -> miércoles | BS8: =+BL8 -> 45770 | BT8: =BM8/1000 -> 0 | BU8: =BN8*$CA$9/$CA$8/1000 -> 0 | BV8: =BO8*$CA$10/$CA$8/1000 -> 0 | BW8: =BP8*$CA$11/$CA$8/1000 -> 0 | BX8: =+BT8+BU8+BV8+BW8 -> 0 | BZ8: Gas Natural | CA8: 8400 | CC8: =+BL8 -> 45770
A9: 45771 | B9: 117.3 | C9: 30.1 | D9: 33.7 | E9: 37.8 | F9: 5.1 | H9: 27.2 | I9: 10.4 | J9: 30.9 | K9: =SUM(H9:J9) -> 68.5 | M9: 2.6 | N9: 26.7 | O9: =SUM(M9:N9) -> 29.3 | Q9: 21.6 | R9: 0 | S9: 0 | T9: =SUM(Q9:S9) -> 21.6 | AF9: 226.07 | AG9: =+AF9-AF8 -> 3.39 | AH9: 215 | AI9: 235 | AJ9: NORMAL | AK9: 120.80037 | AL9: =+AK9-AK8 -> -1.390474 | AM9: 110 | AN9: 142 | AO9: NORMAL | AQ9: 73 | AR9: 84 | AT9: 12 | AU9: 17 | BL9: =+A9 -> 45771 | BR9: =+TEXT(BS9,"dddd") -> jueves | BS9: =+BL9 -> 45771 | BT9: =BM9/1000 -> 0 | BU9: =BN9*$CA$9/$CA$8/1000 -> 0 | BV9: =BO9*$CA$10/$CA$8/1000 -> 0 | BW9: =BP9*$CA$11/$CA$8/1000 -> 0 | BX9: =+BT9+BU9+BV9+BW9 -> 0 | BZ9: Gas Oil | CA9: 8580 | CC9: =+BL9 -> 45771
A10: 45772 | B10: 115.5 | C10: 31.6 | D10: 32.5 | E10: 35.2 | F10: 5 | H10: 27.4 | I10: 10.5 | J10: 32.2 | K10: =SUM(H10:J10) -> 70.1 | M10: 2.6 | N10: 28.3 | O10: =SUM(M10:N10) -> 30.9 | Q10: 19.3 | R10: 0 | S10: 0 | T10: =SUM(Q10:S10) -> 19.3 | AF10: 229.8 | AG10: =+AF10-AF9 -> 3.73 | AH10: 215 | AI10: 235 | AJ10: NORMAL | AK10: 121.85152 | AL10: =+AK10-AK9 -> 1.05115 | AM10: 110 | AN10: 142 | AO10: NORMAL | AQ10: 73 | AR10: 84 | AT10: 12 | AU10: 17 | BL10: =+A10 -> 45772 | BR10: =+TEXT(BS10,"dddd") -> viernes | BS10: =+BL10 -> 45772 | BT10: =BM10/1000 -> 0 | BU10: =BN10*$CA$9/$CA$8/1000 -> 0 | BV10: =BO10*$CA$10/$CA$8/1000 -> 0 | BW10: =BP10*$CA$11/$CA$8/1000 -> 0 | BX10: =+BT10+BU10+BV10+BW10 -> 0 | BZ10: Fuel Oil | CA10: 9800 | CC10: =+BL10 -> 45772
A11: 45773 | B11: 113.1 | C11: 34.4 | D11: 31.5 | E11: 30.7 | F11: 6.1 | H11: 27.6 | I11: 10.6 | J11: 33.3 | K11: =SUM(H11:J11) -> 71.5 | M11: 2.8 | N11: 30.5 | O11: =SUM(M11:N11) -> 33.3 | Q11: 14.9 | R11: 0 | S11: 0 | T11: =SUM(Q11:S11) -> 14.9 | AF11: 231.78 | AG11: =+AF11-AF10 -> 1.98 | AH11: 215 | AI11: 235 | AJ11: NORMAL | AK11: 126.49709 | AL11: =+AK11-AK10 -> 4.645568 | AM11: 110 | AN11: 142 | AO11: NORMAL | AQ11: 73 | AR11: 84 | AT11: 12 | AU11: 17 | BL11: =+A11 -> 45773 | BR11: =+TEXT(BS11,"dddd") -> sábado | BS11: =+BL11 -> 45773 | BT11: =BM11/1000 -> 0 | BU11: =BN11*$CA$9/$CA$8/1000 -> 0 | BV11: =BO11*$CA$10/$CA$8/1000 -> 0 | BW11: =BP11*$CA$11/$CA$8/1000 -> 0 | BX11: =+BT11+BU11+BV11+BW11 -> 0 | BZ11: Carbón | CA11: 5400 | CC11: =+BL11 -> 45773
A12: 45774 | B12: 119.1 | C12: 33.7 | D12: 31.4 | E12: 29.7 | F12: 7 | H12: 29.7 | I12: 10.3 | J12: 33 | K12: =SUM(H12:J12) -> 73 | M12: 2.7 | N12: 33.6 | O12: =SUM(M12:N12) -> 36.3 | Q12: 15.7 | R12: 0 | S12: 0 | T12: =SUM(Q12:S12) -> 15.7 | AF12: 234.11 | AG12: =+AF12-AF11 -> 2.33 | AH12: 215 | AI12: 235 | AJ12: NORMAL | AK12: 130.0702 | AL12: =+AK12-AK11 -> 3.573112 | AM12: 110 | AN12: 142 | AO12: NORMAL | AQ12: 73 | AR12: 84 | AT12: 12 | AU12: 17 | BL12: =+A12 -> 45774 | BR12: =+TEXT(BS12,"dddd") -> domingo | BS12: =+BL12 -> 45774 | BT12: =BM12/1000 -> 0 | BU12: =BN12*$CA$9/$CA$8/1000 -> 0 | BV12: =BO12*$CA$10/$CA$8/1000 -> 0 | BW12: =BP12*$CA$11/$CA$8/1000 -> 0 | BX12: =+BT12+BU12+BV12+BW12 -> 0 | CC12: =+BL12 -> 45774
A13: 45775 | B13: 131.8 | C13: 36.4 | D13: 33.2 | E13: 40.8 | F13: 7.7 | H13: 27.3 | I13: 9.9 | J13: 34.8 | K13: =SUM(H13:J13) -> 72 | M13: 2.6 | N13: 34.8 | O13: =SUM(M13:N13) -> 37.4 | Q13: 15.2 | R13: 0 | S13: 0 | T13: =SUM(Q13:S13) -> 15.2 | AF13: 226.83 | AG13: =+AF13-AF12 -> -7.28 | AH13: 215 | AI13: 235 | AJ13: NORMAL | AK13: 130.17792 | AL13: =+AK13-AK12 -> 0.10772 | AM13: 110 | AN13: 142 | AO13: NORMAL | AP13: 85.75 | AQ13: 73 | AR13: 84 | AS13: 15.63 | AT13: 12 | AU13: 17 | BL13: =+A13 -> 45775 | BR13: =+TEXT(BS13,"dddd") -> lunes | BS13: =+BL13 -> 45775 | BT13: =BM13/1000 -> 0 | BU13: =BN13*$CA$9/$CA$8/1000 -> 0 | BV13: =BO13*$CA$10/$CA$8/1000 -> 0 | BW13: =BP13*$CA$11/$CA$8/1000 -> 0 | BX13: =+BT13+BU13+BV13+BW13 -> 0 | CC13: =+BL13 -> 45775
A14: 45776 | B14: 133.2 | C14: 35.4 | D14: 33.1 | E14: 39.8 | F14: 8.7 | H14: 28.7 | I14: 10 | J14: 34.1 | K14: =SUM(H14:J14) -> 72.8 | M14: 2.6 | N14: 35.3 | O14: =SUM(M14:N14) -> 37.9 | Q14: 16.5 | R14: 0 | S14: 0 | T14: =SUM(Q14:S14) -> 16.5 | AF14: 221.75 | AG14: =+AF14-AF13 -> -5.08 | AH14: 215 | AI14: 235 | AJ14: NORMAL | AK14: 129.24379 | AL14: =+AK14-AK13 -> -0.934128 | AM14: 110 | AN14: 142 | AO14: NORMAL | AP14: 45.6 | AQ14: 73 | AR14: 84 | AS14: 15.72 | AT14: 12 | AU14: 17 | BL14: =+A14 -> 45776 | BR14: =+TEXT(BS14,"dddd") -> martes | BS14: =+BL14 -> 45776 | BT14: =BM14/1000 -> 0 | BU14: =BN14*$CA$9/$CA$8/1000 -> 0 | BV14: =BO14*$CA$10/$CA$8/1000 -> 0 | BW14: =BP14*$CA$11/$CA$8/1000 -> 0 | BX14: =+BT14+BU14+BV14+BW14 -> 0 | CC14: =+BL14 -> 45776
A15: 45777 | B15: 127.1 | C15: 34.7 | D15: 34.4 | E15: 38.4 | F15: 8.8 | H15: 28.4 | I15: 10.2 | J15: 32.3 | K15: =SUM(H15:J15) -> 70.9 | M15: 2.6 | N15: 34.1 | O15: =SUM(M15:N15) -> 36.7 | Q15: 16.8 | R15: 0 | S15: 0 | T15: =SUM(Q15:S15) -> 16.8 | V15: 13 | W15: 23 | X15: =+AVERAGE(V15:W15) -> 18 | Y15: 13 | Z15: 22 | AA15: =+AVERAGE(Y15:Z15) -> 17.5 | AB15: 2 | AC15: 15 | AD15: =+AVERAGE(AB15:AC15) -> 8.5 | AF15: 223.18 | AG15: =+AF15-AF14 -> 1.43 | AH15: 215 | AI15: 235 | AJ15: NORMAL | AK15: 129.36844 | AL15: =+AK15-AK14 -> 0.124648 | AM15: 110 | AN15: 142 | AO15: NORMAL | AP15: 75.6 | AQ15: 73 | AR15: 84 | AS15: 14.49 | AT15: 12 | AU15: 17 | AY15: Fecha | AZ15: Recepción GPM | BA15: Entrega GPM | BB15: GNL Esc | BC15: Bolivia | BD15: Inyección Total [m3] | BE15: Inyección Total [Dam3] | BG15: Temp Max | BH15: Temp Min | BI15: Temp Prom | BL15: =+A15 -> 45777 | BR15: =+TEXT(BS15,"dddd") -> miércoles | BS15: =+BL15 -> 45777 | BT15: =BM15/1000 -> 0 | BU15: =BN15*$CA$9/$CA$8/1000 -> 0 | BV15: =BO15*$CA$10/$CA$8/1000 -> 0 | BW15: =BP15*$CA$11/$CA$8/1000 -> 0 | BX15: =+BT15+BU15+BV15+BW15 -> 0 | CC15: =+BL15 -> 45777
A16: 45778 | B16: 105.7 | C16: 31.2 | D16: 29.7 | E16: 28.9 | F16: 7 | H16: 26.9 | I16: 9.3 | J16: 37.5 | K16: =SUM(H16:J16) -> 73.7 | M16: 2.6 | N16: 34.6 | O16: =SUM(M16:N16) -> 37.2 | Q16: 8.7 | R16: 0 | S16: 0 | T16: =SUM(Q16:S16) -> 8.7 | V16: 11.6 | W16: 23 | X16: =+AVERAGE(V16:W16) -> 17.3 | Y16: 12.3 | Z16: 20.3 | AA16: =+AVERAGE(Y16:Z16) -> 16.3 | AB16: 0 | AC16: 7.4 | AD16: =+AVERAGE(AB16:AC16) -> 3.7 | AF16: 230.7 | AG16: =+AF16-AF15 -> 7.52 | AH16: 215 | AI16: 235 | AJ16: NORMAL | AK16: 135.7487 | AL16: =+AK16-AK15 -> 6.38026 | AM16: 110 | AN16: 142 | AO16: NORMAL | AP16: 75.06 | AQ16: 73 | AR16: 84 | AS16: 14.37 | AT16: 12 | AU16: 17 | AY16: 45413 | AZ16: 12146888 | BA16: 11328757 | BB16: 0 | BC16: 4932281 | BD16: =+AZ16+BB16+BC16 -> 17079169 | BE16: =+BD16/1000 -> 17079.169 | BG16: 18 | BH16: 14 | BI16: =+AVERAGE(BG16:BH16) -> 16 | BL16: =+A16 -> 45778 | BR16: =+TEXT(BS16,"dddd") -> jueves | BS16: =+BL16 -> 45778 | BT16: =BM16/1000 -> 0 | BU16: =BN16*$CA$9/$CA$8/1000 -> 0 | BV16: =BO16*$CA$10/$CA$8/1000 -> 0 | BW16: =BP16*$CA$11/$CA$8/1000 -> 0 | BX16: =+BT16+BU16+BV16+BW16 -> 0 | CC16: =+BL16 -> 45778
A17: 45779 | B17: 120.8 | C17: 31.3 | D17: 32.6 | E17: 37.7 | F17: 7.5 | H17: 25.6 | I17: 8.6 | J17: 38.8 | K17: =SUM(H17:J17) -> 73 | M17: 2.7 | N17: 33.4 | O17: =SUM(M17:N17) -> 36.1 | Q17: 4.1 | R17: 0 | S17: 0 | T17: =SUM(Q17:S17) -> 4.1 | V17: 12.4 | W17: 19.8 | X17: =+AVERAGE(V17:W17) -> 16.1 | Y17: 12.7 | Z17: 20.7 | AA17: =+AVERAGE(Y17:Z17) -> 16.7 | AB17: 0.4 | AC17: 7.2 | AD17: =+AVERAGE(AB17:AC17) -> 3.8 | AF17: 227.43 | AG17: =+AF17-AF16 -> -3.27 | AH17: 215 | AI17: 235 | AJ17: NORMAL | AK17: 131.51282 | AL17: =+AK17-AK16 -> -4.23588 | AM17: 110 | AN17: 142 | AO17: NORMAL | AP17: 78.73 | AQ17: 73 | AR17: 84 | AS17: 14.55 | AT17: 12 | AU17: 17 | AY17: =+AY16+1 -> 45414 | AZ17: 11973299 | BA17: 11944549 | BB17: 0 | BC17: 4939458 | BD17: =+AZ17+BB17+BC17 -> 16912757 | BE17: =+BD17/1000 -> 16912.757 | BG17: 16 | BH17: 10 | BI17: =+AVERAGE(BG17:BH17) -> 13 | BL17: =+A17 -> 45779 | BR17: =+TEXT(BS17,"dddd") -> viernes | BS17: =+BL17 -> 45779 | BT17: =BM17/1000 -> 0 | BU17: =BN17*$CA$9/$CA$8/1000 -> 0 | BV17: =BO17*$CA$10/$CA$8/1000 -> 0 | BW17: =BP17*$CA$11/$CA$8/1000 -> 0 | BX17: =+BT17+BU17+BV17+BW17 -> 0 | CC17: =+BL17 -> 45779
A18: 45780 | B18: 111.8 | C18: 30.1 | D18: 31.2 | E18: 32.8 | F18: 6.4 | H18: 25 | I18: 8.7 | J18: 38 | K18: =SUM(H18:J18) -> 71.7 | M18: 2.7 | N18: 32.4 | O18: =SUM(M18:N18) -> 35.1 | Q18: 3.7 | R18: 0 | S18: 0 | T18: =SUM(Q18:S18) -> 3.7 | V18: 11 | W18: 20.4 | X18: =+AVERAGE(V18:W18) -> 15.7 | Y18: 12 | Z18: 20.7 | AA18: =+AVERAGE(Y18:Z18) -> 16.35 | AB18: 0 | AC18: 7.6 | AD18: =+AVERAGE(AB18:AC18) -> 3.8 | AF18: 225.91 | AG18: =+AF18-AF17 -> -1.52 | AH18: 215 | AI18: 235 | AJ18: NORMAL | AK18: 131.62327 | AL18: =+AK18-AK17 -> 0.11045 | AM18: 110 | AN18: 142 | AO18: NORMAL | AP18: 80.31 | AQ18: 73 | AR18: 84 | AS18: 14.67 | AT18: 12 | AU18: 17 | AY18: =+AY17+1 -> 45415 | AZ18: 11075230 | BA18: 11845606 | BB18: 0 | BC18: 4955251 | BD18: =+AZ18+BB18+BC18 -> 16030481 | BE18: =+BD18/1000 -> 16030.481 | BG18: 15 | BH18: 9 | BI18: =+AVERAGE(BG18:BH18) -> 12 | BL18: =+A18 -> 45780 | BR18: =+TEXT(BS18,"dddd") -> sábado | BS18: =+BL18 -> 45780 | BT18: =BM18/1000 -> 0 | BU18: =BN18*$CA$9/$CA$8/1000 -> 0 | BV18: =BO18*$CA$10/$CA$8/1000 -> 0 | BW18: =BP18*$CA$11/$CA$8/1000 -> 0 | BX18: =+BT18+BU18+BV18+BW18 -> 0 | CC18: =+BL18 -> 45780
A19: 45781 | B19: 110 | C19: 30.1 | D19: 30.5 | E19: 31.2 | F19: 5.9 | H19: 26.1 | I19: 9.5 | J19: 38.5 | K19: =SUM(H19:J19) -> 74.1 | M19: 2.7 | N19: 32.1 | O19: =SUM(M19:N19) -> 34.8 | Q19: 7.4 | R19: 0 | S19: 0 | T19: =SUM(Q19:S19) -> 7.4 | V19: 17 | W19: 24 | X19: =+AVERAGE(V19:W19) -> 20.5 | Y19: 17 | Z19: 24 | AA19: =+AVERAGE(Y19:Z19) -> 20.5 | AB19: 0 | AC19: 9 | AD19: =+AVERAGE(AB19:AC19) -> 4.5 | AF19: 229.68 | AG19: =+AF19-AF18 -> 3.77 | AH19: 215 | AI19: 235 | AJ19: NORMAL | AK19: 134.26583 | AL19: =+AK19-AK18 -> 2.64256 | AM19: 110 | AN19: 142 | AO19: NORMAL | AP19: 79.28 | AQ19: 73 | AR19: 84 | AS19: 14.75 | AT19: 12 | AU19: 17 | AY19: =+AY18+1 -> 45416 | AZ19: 12910151 | BA19: 12067435 | BB19: 0 | BC19: 4944689 | BD19: =+AZ19+BB19+BC19 -> 17854840 | BE19: =+BD19/1000 -> 17854.84 | BG19: 17 | BH19: 14 | BI19: =+AVERAGE(BG19:BH19) -> 15.5 | BL19: =+A19 -> 45781 | BR19: =+TEXT(BS19,"dddd") -> domingo | BS19: =+BL19 -> 45781 | BT19: =BM19/1000 -> 0 | BU19: =BN19*$CA$9/$CA$8/1000 -> 0 | BV19: =BO19*$CA$10/$CA$8/1000 -> 0 | BW19: =BP19*$CA$11/$CA$8/1000 -> 0 | BX19: =+BT19+BU19+BV19+BW19 -> 0 | CC19: =+BL19 -> 45781
A20: 45782 | B20: 123.3 | C20: 36.5 | D20: 32 | E20: 37.8 | F20: 8.1 | H20: 26 | I20: 9.3 | J20: 39.2 | K20: =SUM(H20:J20) -> 74.5 | M20: 2.6 | N20: 32.7 | O20: =SUM(M20:N20) -> 35.3 | Q20: 8.8 | R20: 0 | S20: 0 | T20: =SUM(Q20:S20) -> 8.8 | V20: 15 | W20: 25 | X20: =+AVERAGE(V20:W20) -> 20 | Y20: 15 | Z20: 19 | AA20: =+AVERAGE(Y20:Z20) -> 17 | AB20: 2 | AC20: 11 | AD20: =+AVERAGE(AB20:AC20) -> 6.5 | AF20: 228.41 | AG20: =+AF20-AF19 -> -1.27 | AH20: 215 | AI20: 235 | AJ20: NORMAL | AK20: 128.72554 | AL20: =+AK20-AK19 -> -5.54029 | AM20: 110 | AN20: 142 | AO20: NORMAL | AP20: 82.98 | AQ20: 73 | AR20: 84 | AS20: 15.15 | AT20: 12 | AU20: 17 | AY20: =+AY19+1 -> 45417 | AZ20: 12221049 | BA20: 11614173 | BB20: 0 | BC20: 4946012 | BD20: =+AZ20+BB20+BC20 -> 17167061 | BE20: =+BD20/1000 -> 17167.061 | BG20: 20 | BH20: 18 | BI20: =+AVERAGE(BG20:BH20) -> 19 | BL20: =+A20 -> 45782 | BR20: =+TEXT(BS20,"dddd") -> lunes | BS20: =+BL20 -> 45782 | BT20: =BM20/1000 -> 0 | BU20: =BN20*$CA$9/$CA$8/1000 -> 0 | BV20: =BO20*$CA$10/$CA$8/1000 -> 0 | BW20: =BP20*$CA$11/$CA$8/1000 -> 0 | BX20: =+BT20+BU20+BV20+BW20 -> 0 | CC20: =+BL20 -> 45782
A21: 45783 | B21: 121.6 | C21: 35.2 | D21: 32.6 | E21: 37.1 | F21: 4.8 | H21: 25.3 | I21: 9.4 | J21: 40.3 | K21: =SUM(H21:J21) -> 75 | M21: 2.8 | N21: 28.2 | O21: =SUM(M21:N21) -> 31 | Q21: 12.1 | R21: 0 | S21: 0 | T21: =SUM(Q21:S21) -> 12.1 | V21: 18 | W21: 24 | X21: =+AVERAGE(V21:W21) -> 21 | Y21: 16 | Z21: 22 | AA21: =+AVERAGE(Y21:Z21) -> 19 | AB21: 3 | AC21: 9 | AD21: =+AVERAGE(AB21:AC21) -> 6 | AF21: 230.71 | AG21: =+AF21-AF20 -> 2.3 | AH21: 215 | AI21: 235 | AJ21: NORMAL | AK21: 125.17737 | AL21: =+AK21-AK20 -> -3.548169 | AM21: 110 | AN21: 142 | AO21: NORMAL | AP21: 79.61 | AQ21: 73 | AR21: 84 | AS21: 14.58 | AT21: 12 | AU21: 17 | AY21: =+AY20+1 -> 45418 | AZ21: 10510527 | BA21: 9583101 | BB21: 3455219 | BC21: 4945767 | BD21: =+AZ21+BB21+BC21 -> 18911513 | BE21: =+BD21/1000 -> 18911.513 | BG21: 20 | BH21: 17 | BI21: =+AVERAGE(BG21:BH21) -> 18.5 | BL21: =+A21 -> 45783 | BR21: =+TEXT(BS21,"dddd") -> martes | BS21: =+BL21 -> 45783 | BT21: =BM21/1000 -> 0 | BU21: =BN21*$CA$9/$CA$8/1000 -> 0 | BV21: =BO21*$CA$10/$CA$8/1000 -> 0 | BW21: =BP21*$CA$11/$CA$8/1000 -> 0 | BX21: =+BT21+BU21+BV21+BW21 -> 0 | CC21: =+BL21 -> 45783
A22: 45784 | B22: 126.2 | C22: 36 | D22: 33.6 | E22: 39.2 | F22: 5.3 | H22: 25.3 | I22: 9 | J22: 39.6 | K22: =SUM(H22:J22) -> 73.9 | M22: 2.6 | N22: 31.5 | O22: =SUM(M22:N22) -> 34.1 | Q22: 13.3 | R22: 0 | S22: 0 | T22: =SUM(Q22:S22) -> 13.3 | V22: 17 | W22: 22 | X22: =+AVERAGE(V22:W22) -> 19.5 | Y22: 15 | Z22: 22 | AA22: =+AVERAGE(Y22:Z22) -> 18.5 | AB22: 1 | AC22: 10 | AD22: =+AVERAGE(AB22:AC22) -> 5.5 | AF22: 226.73 | AG22: =+AF22-AF21 -> -3.98 | AH22: 215 | AI22: 235 | AJ22: NORMAL | AK22: 124.02095 | AL22: =+AK22-AK21 -> -1.156421 | AM22: 110 | AN22: 142 | AO22: NORMAL | AP22: 79.07 | AQ22: 73 | AR22: 84 | AS22: 14.36 | AT22: 12 | AU22: 17 | AY22: =+AY21+1 -> 45419 | AZ22: 9160657 | BA22: 9379741 | BB22: 3012565 | BC22: 4945964 | BD22: =+AZ22+BB22+BC22 -> 17119186 | BE22: =+BD22/1000 -> 17119.186 | BG22: 19 | BH22: 17 | BI22: =+AVERAGE(BG22:BH22) -> 18 | BL22: =+A22 -> 45784 | BR22: =+TEXT(BS22,"dddd") -> miércoles | BS22: =+BL22 -> 45784 | BT22: =BM22/1000 -> 0 | BU22: =BN22*$CA$9/$CA$8/1000 -> 0 | BV22: =BO22*$CA$10/$CA$8/1000 -> 0 | BW22: =BP22*$CA$11/$CA$8/1000 -> 0 | BX22: =+BT22+BU22+BV22+BW22 -> 0 | CC22: =+BL22 -> 45784
A23: 45785 | B23: 127.8 | C23: 36.2 | D23: 33.8 | E23: 39.1 | F23: 9.4 | H23: 26.4 | I23: 8.5 | J23: 40 | K23: =SUM(H23:J23) -> 74.9 | M23: 2.6 | N23: 35 | O23: =SUM(M23:N23) -> 37.6 | Q23: 9.8 | R23: 0 | S23: 0 | T23: =SUM(Q23:S23) -> 9.8 | V23: 16 | W23: 21 | X23: =+AVERAGE(V23:W23) -> 18.5 | Y23: 18 | Z23: 25 | AA23: =+AVERAGE(Y23:Z23) -> 21.5 | AB23: 1 | AC23: 9 | AD23: =+AVERAGE(AB23:AC23) -> 5 | AF23: 222.48 | AG23: =+AF23-AF22 -> -4.25 | AH23: 215 | AI23: 235 | AJ23: NORMAL | AK23: 122.69134 | AL23: =+AK23-AK22 -> -1.329608 | AM23: 110 | AN23: 142 | AO23: NORMAL | AP23: 82.81 | AQ23: 73 | AR23: 84 | AS23: 14.71 | AT23: 12 | AU23: 17 | AY23: =+AY22+1 -> 45420 | AZ23: 10499366 | BA23: 11207845 | BB23: 3020977 | BC23: 4945930 | BD23: =+AZ23+BB23+BC23 -> 18466273 | BE23: =+BD23/1000 -> 18466.273 | BG23: 19 | BH23: 14 | BI23: =+AVERAGE(BG23:BH23) -> 16.5 | BL23: =+A23 -> 45785 | BR23: =+TEXT(BS23,"dddd") -> jueves | BS23: =+BL23 -> 45785 | BT23: =BM23/1000 -> 0 | BU23: =BN23*$CA$9/$CA$8/1000 -> 0 | BV23: =BO23*$CA$10/$CA$8/1000 -> 0 | BW23: =BP23*$CA$11/$CA$8/1000 -> 0 | BX23: =+BT23+BU23+BV23+BW23 -> 0 | CC23: =+BL23 -> 45785
A24: 45786 | B24: 126.3 | C24: 36.3 | D24: 34.4 | E24: 31.8 | F24: 9 | H24: 26.8 | I24: 9 | J24: 39.2 | K24: =SUM(H24:J24) -> 75 | M24: 2.7 | N24: 37.8 | O24: =SUM(M24:N24) -> 40.5 | Q24: 12.5 | R24: 0 | S24: 0 | T24: =SUM(Q24:S24) -> 12.5 | V24: 16 | W24: 24 | X24: =+AVERAGE(V24:W24) -> 20 | Y24: 13 | Z24: 21 | AA24: =+AVERAGE(Y24:Z24) -> 17 | AB24: 3 | AC24: 10 | AD24: =+AVERAGE(AB24:AC24) -> 6.5 | AF24: 225.55 | AG24: =+AF24-AF23 -> 3.07 | AH24: 215 | AI24: 235 | AJ24: NORMAL | AK24: 121.24765 | AL24: =+AK24-AK23 -> -1.443692 | AM24: 110 | AN24: 142 | AO24: NORMAL | AP24: 78.23 | AQ24: 73 | AR24: 84 | AS24: 14.89 | AT24: 12 | AU24: 17 | AY24: =+AY23+1 -> 45421 | AZ24: 9516512 | BA24: 10886415 | BB24: 3009160 | BC24: 4996364 | BD24: =+AZ24+BB24+BC24 -> 17522036 | BE24: =+BD24/1000 -> 17522.036 | BG24: 16 | BH24: 8 | BI24: =+AVERAGE(BG24:BH24) -> 12 | BL24: =+A24 -> 45786 | BR24: =+TEXT(BS24,"dddd") -> viernes | BS24: =+BL24 -> 45786 | BT24: =BM24/1000 -> 0 | BU24: =BN24*$CA$9/$CA$8/1000 -> 0 | BV24: =BO24*$CA$10/$CA$8/1000 -> 0 | BW24: =BP24*$CA$11/$CA$8/1000 -> 0 | BX24: =+BT24+BU24+BV24+BW24 -> 0 | CC24: =+BL24 -> 45786
A25: 45787 | B25: 118.7 | C25: 35 | D25: 32.6 | E25: 28.5 | F25: 9 | H25: 27.3 | I25: 10 | J25: 35 | K25: =SUM(H25:J25) -> 72.3 | M25: 2.6 | N25: 36.8 | O25: =SUM(M25:N25) -> 39.4 | Q25: 14.2 | R25: 0 | S25: 0 | T25: =SUM(Q25:S25) -> 14.2 | V25: 14 | W25: 25 | X25: =+AVERAGE(V25:W25) -> 19.5 | Y25: 14 | Z25: 21 | AA25: =+AVERAGE(Y25:Z25) -> 17.5 | AB25: 6 | AC25: 13 | AD25: =+AVERAGE(AB25:AC25) -> 9.5 | AF25: 229.55 | AG25: =+AF25-AF24 -> 4 | AH25: 215 | AI25: 235 | AJ25: NORMAL | AK25: 124.31696 | AL25: =+AK25-AK24 -> 3.06931 | AM25: 110 | AN25: 142 | AO25: NORMAL | AP25: 80.98 | AQ25: 73 | AR25: 84 | AS25: 14.82 | AT25: 12 | AU25: 17 | AY25: =+AY24+1 -> 45422 | AZ25: 10120449 | BA25: 10797335 | BB25: 8904883 | BC25: 4945959 | BD25: =+AZ25+BB25+BC25 -> 23971291 | BE25: =+BD25/1000 -> 23971.291 | BG25: 17 | BH25: 14 | BI25: =+AVERAGE(BG25:BH25) -> 15.5 | BL25: =+A25 -> 45787 | BR25: =+TEXT(BS25,"dddd") -> sábado | BS25: =+BL25 -> 45787 | BT25: =BM25/1000 -> 0 | BU25: =BN25*$CA$9/$CA$8/1000 -> 0 | BV25: =BO25*$CA$10/$CA$8/1000 -> 0 | BW25: =BP25*$CA$11/$CA$8/1000 -> 0 | BX25: =+BT25+BU25+BV25+BW25 -> 0 | CC25: =+BL25 -> 45787
A26: 45788 | B26: 109 | C26: 33.5 | D26: 32 | E26: 26.7 | F26: 6.5 | H26: 25.4 | I26: 10.4 | J26: 36.2 | K26: =SUM(H26:J26) -> 72 | M26: 2.6 | N26: 36.3 | O26: =SUM(M26:N26) -> 38.9 | Q26: 9.6 | R26: 0 | S26: 0 | T26: =SUM(Q26:S26) -> 9.6 | V26: 15 | W26: 26 | X26: =+AVERAGE(V26:W26) -> 20.5 | Y26: 14 | Z26: 19 | AA26: =+AVERAGE(Y26:Z26) -> 16.5 | AB26: 2 | AC26: 12 | AD26: =+AVERAGE(AB26:AC26) -> 7 | AF26: 231.12 | AG26: =+AF26-AF25 -> 1.57 | AH26: 215 | AI26: 235 | AJ26: NORMAL | AK26: 134.24806 | AL26: =+AK26-AK25 -> 9.9311 | AM26: 110 | AN26: 142 | AO26: NORMAL | AP26: 81.94 | AQ26: 73 | AR26: 84 | AS26: 14.54 | AT26: 12 | AU26: 17 | AY26: =+AY25+1 -> 45423 | AZ26: 12677022 | BA26: 10823842 | BB26: 7103139 | BC26: 4972656 | BD26: =+AZ26+BB26+BC26 -> 24752817 | BE26: =+BD26/1000 -> 24752.817 | BG26: 17 | BH26: 12 | BI26: =+AVERAGE(BG26:BH26) -> 14.5 | BL26: =+A26 -> 45788 | BR26: =+TEXT(BS26,"dddd") -> domingo | BS26: =+BL26 -> 45788 | BT26: =BM26/1000 -> 0 | BU26: =BN26*$CA$9/$CA$8/1000 -> 0 | BV26: =BO26*$CA$10/$CA$8/1000 -> 0 | BW26: =BP26*$CA$11/$CA$8/1000 -> 0 | BX26: =+BT26+BU26+BV26+BW26 -> 0 | CC26: =+BL26 -> 45788
A27: 45789 | B27: 124.2 | C27: 36 | D27: 33.8 | E27: 31.8 | F27: 8.3 | H27: 26.2 | I27: 10.4 | J27: 37.9 | K27: =SUM(H27:J27) -> 74.5 | M27: 2.6 | N27: 34.3 | O27: =SUM(M27:N27) -> 36.9 | Q27: 11.8 | R27: 0 | S27: 0 | T27: =SUM(Q27:S27) -> 11.8 | V27: 14 | W27: 22 | X27: =+AVERAGE(V27:W27) -> 18 | Y27: 13 | Z27: 19 | AA27: =+AVERAGE(Y27:Z27) -> 16 | AB27: 3 | AC27: 12 | AD27: =+AVERAGE(AB27:AC27) -> 7.5 | AF27: 232.91 | AG27: =+AF27-AF26 -> 1.79 | AH27: 215 | AI27: 235 | AJ27: NORMAL | AK27: 131.42467 | AL27: =+AK27-AK26 -> -2.82339 | AM27: 110 | AN27: 142 | AO27: NORMAL | AP27: 84 | AQ27: 73 | AR27: 84 | AS27: 16.36 | AT27: 12 | AU27: 17 | AY27: =+AY26+1 -> 45424 | AZ27: 9497858 | BA27: 11666052 | BB27: 7022515 | BC27: 4975591 | BD27: =+AZ27+BB27+BC27 -> 21495964 | BE27: =+BD27/1000 -> 21495.964 | BG27: 13 | BH27: 10 | BI27: =+AVERAGE(BG27:BH27) -> 11.5 | BL27: =+A27 -> 45789 | BR27: =+TEXT(BS27,"dddd") -> lunes | BS27: =+BL27 -> 45789 | BT27: =BM27/1000 -> 0 | BU27: =BN27*$CA$9/$CA$8/1000 -> 0 | BV27: =BO27*$CA$10/$CA$8/1000 -> 0 | BW27: =BP27*$CA$11/$CA$8/1000 -> 0 | BX27: =+BT27+BU27+BV27+BW27 -> 0 | CC27: =+BL27 -> 45789
A28: 45790 | B28: 125.2 | C28: 35.4 | D28: 33.1 | E28: 34.4 | F28: =7.9+0.3 -> 8.2 | H28: 25.2 | I28: 10.4 | J28: 36.2 | K28: =SUM(H28:J28) -> 71.8 | M28: 2.4 | N28: 33.1 | O28: =SUM(M28:N28) -> 35.5 | Q28: 12.9 | R28: 0 | S28: 0 | T28: =SUM(Q28:S28) -> 12.9 | V28: 14 | W28: 25 | X28: =+AVERAGE(V28:W28) -> 19.5 | Y28: 14 | Z28: 21 | AA28: =+AVERAGE(Y28:Z28) -> 17.5 | AB28: 6 | AC28: 12 | AD28: =+AVERAGE(AB28:AC28) -> 9 | AF28: 233.22 | AG28: =+AF28-AF27 -> 0.31 | AH28: 215 | AI28: 235 | AJ28: NORMAL | AK28: 126.1273 | AL28: =+AK28-AK27 -> -5.29737 | AM28: 110 | AN28: 142 | AO28: NORMAL | AP28: 83.2 | AQ28: 73 | AR28: 84 | AS28: 16.15 | AT28: 12 | AU28: 17 | AY28: =+AY27+1 -> 45425 | AZ28: 12217904 | BA28: 11853085 | BB28: 13999572 | BC28: 5000760 | BD28: =+AZ28+BB28+BC28 -> 31218236 | BE28: =+BD28/1000 -> 31218.236 | BG28: 14 | BH28: 6 | BI28: =+AVERAGE(BG28:BH28) -> 10 | BL28: =+A28 -> 45790 | BR28: =+TEXT(BS28,"dddd") -> martes | BS28: =+BL28 -> 45790 | BT28: =BM28/1000 -> 0 | BU28: =BN28*$CA$9/$CA$8/1000 -> 0 | BV28: =BO28*$CA$10/$CA$8/1000 -> 0 | BW28: =BP28*$CA$11/$CA$8/1000 -> 0 | BX28: =+BT28+BU28+BV28+BW28 -> 0 | CC28: =+BL28 -> 45790
A29: 45791 | B29: 122.8 | C29: 33.7 | D29: 34.5 | E29: 37.1 | F29: 6.7 | H29: 25.4 | I29: 10.3 | J29: 33.9 | K29: =SUM(H29:J29) -> 69.6 | M29: 2.5 | N29: 31.5 | O29: =SUM(M29:N29) -> 34 | Q29: 16.1 | R29: 0 | S29: 0 | T29: =SUM(Q29:S29) -> 16.1 | V29: 15 | W29: 24 | X29: =+AVERAGE(V29:W29) -> 19.5 | Y29: 16 | Z29: 23 | AA29: =+AVERAGE(Y29:Z29) -> 19.5 | AB29: 5 | AC29: 11 | AD29: =+AVERAGE(AB29:AC29) -> 8 | AF29: 229.24 | AG29: =+AF29-AF28 -> -3.98 | AH29: 215 | AI29: 235 | AJ29: NORMAL | AK29: 126.87546 | AL29: =+AK29-AK28 -> 0.74816 | AM29: 110 | AN29: 142 | AO29: NORMAL | AP29: 82.42 | AQ29: 73 | AR29: 84 | AS29: 16.21 | AT29: 12 | AU29: 17 | AY29: =+AY28+1 -> 45426 | AZ29: 8527699 | BA29: 11999772 | BB29: 12043327 | BC29: 4977516 | BD29: =+AZ29+BB29+BC29 -> 25548542 | BE29: =+BD29/1000 -> 25548.542 | BG29: 14 | BH29: 7 | BI29: =+AVERAGE(BG29:BH29) -> 10.5 | BL29: =+A29 -> 45791 | BR29: =+TEXT(BS29,"dddd") -> miércoles | BS29: =+BL29 -> 45791 | BT29: =BM29/1000 -> 0 | BU29: =BN29*$CA$9/$CA$8/1000 -> 0 | BV29: =BO29*$CA$10/$CA$8/1000 -> 0 | BW29: =BP29*$CA$11/$CA$8/1000 -> 0 | BX29: =+BT29+BU29+BV29+BW29 -> 0 | CC29: =+BL29 -> 45791
A30: 45792 | B30: 127.3 | C30: 33.1 | D30: 34.5 | E30: 37.2 | F30: 8.9 | H30: 25.9 | I30: 10.2 | J30: 33.2 | K30: =SUM(H30:J30) -> 69.3 | M30: 2.6 | N30: 33.2 | O30: =SUM(M30:N30) -> 35.8 | Q30: 18.3 | R30: 0 | S30: 0 | T30: =SUM(Q30:S30) -> 18.3 | V30: 16 | W30: 24 | X30: =+AVERAGE(V30:W30) -> 20 | Y30: 19 | Z30: 23 | AA30: =+AVERAGE(Y30:Z30) -> 21 | AB30: 7 | AC30: 12 | AD30: =+AVERAGE(AB30:AC30) -> 9.5 | AF30: 226.98 | AG30: =+AF30-AF29 -> -2.26 | AH30: 215 | AI30: 235 | AJ30: NORMAL | AK30: 124.16873 | AL30: =+AK30-AK29 -> -2.706725 | AM30: 110 | AN30: 142 | AO30: NORMAL | AP30: 80.59 | AQ30: 73 | AR30: 84 | AS30: 15.1 | AT30: 12 | AU30: 17 | AY30: =+AY29+1 -> 45427 | AZ30: 11265652 | BA30: 8964539 | BB30: 12051958 | BC30: 4978424 | BD30: =+AZ30+BB30+BC30 -> 28296034 | BE30: =+BD30/1000 -> 28296.034 | BG30: 16 | BH30: 8 | BI30: =+AVERAGE(BG30:BH30) -> 12 | BL30: =+A30 -> 45792 | BR30: =+TEXT(BS30,"dddd") -> jueves | BS30: =+BL30 -> 45792 | BT30: =BM30/1000 -> 0 | BU30: =BN30*$CA$9/$CA$8/1000 -> 0 | BV30: =BO30*$CA$10/$CA$8/1000 -> 0 | BW30: =BP30*$CA$11/$CA$8/1000 -> 0 | BX30: =+BT30+BU30+BV30+BW30 -> 0 | CC30: =+BL30 -> 45792
A31: 45793 | B31: 120.4 | C31: 33.6 | D31: 34.4 | E31: 35.4 | F31: 7.1 | H31: 26 | I31: 10.2 | J31: 34.3 | K31: =SUM(H31:J31) -> 70.5 | M31: 2.6 | N31: 32.1 | O31: =SUM(M31:N31) -> 34.7 | Q31: 20.7 | R31: 0 | S31: 0 | T31: =SUM(Q31:S31) -> 20.7 | V31: 17 | W31: 26 | X31: =+AVERAGE(V31:W31) -> 21.5 | Y31: 18 | Z31: 22 | AA31: =+AVERAGE(Y31:Z31) -> 20 | AB31: 4 | AC31: 11 | AD31: =+AVERAGE(AB31:AC31) -> 7.5 | AF31: 231.65 | AG31: =+AF31-AF30 -> 4.67 | AH31: 215 | AI31: 235 | AJ31: NORMAL | AK31: 124.97541 | AL31: =+AK31-AK30 -> 0.806676 | AM31: 110 | AN31: 142 | AO31: NORMAL | AP31: 79 | AQ31: 73 | AR31: 84 | AS31: 13.35 | AT31: 12 | AU31: 17 | AY31: =+AY30+1 -> 45428 | AZ31: 11109202 | BA31: 11122015 | BB31: 5016919 | BC31: 5104531 | BD31: =+AZ31+BB31+BC31 -> 21230652 | BE31: =+BD31/1000 -> 21230.652 | BG31: 17 | BH31: 10 | BI31: =+AVERAGE(BG31:BH31) -> 13.5 | BL31: =+A31 -> 45793 | BR31: =+TEXT(BS31,"dddd") -> viernes | BS31: =+BL31 -> 45793 | BT31: =BM31/1000 -> 0 | BU31: =BN31*$CA$9/$CA$8/1000 -> 0 | BV31: =BO31*$CA$10/$CA$8/1000 -> 0 | BW31: =BP31*$CA$11/$CA$8/1000 -> 0 | BX31: =+BT31+BU31+BV31+BW31 -> 0 | CC31: =+BL31 -> 45793
A32: 45794 | B32: 115.2 | C32: 34.5 | D32: 31 | E32: 27.4 | F32: 8.2 | H32: 25.7 | I32: 10.1 | J32: 35.4 | K32: =SUM(H32:J32) -> 71.2 | M32: 2.6 | N32: 35.2 | O32: =SUM(M32:N32) -> 37.8 | Q32: 16.3 | R32: 0 | S32: 0 | T32: =SUM(Q32:S32) -> 16.3 | V32: 17 | W32: 27 | X32: =+AVERAGE(V32:W32) -> 22 | Y32: 18 | Z32: 22 | AA32: =+AVERAGE(Y32:Z32) -> 20 | AB32: 0 | AC32: 9 | AD32: =+AVERAGE(AB32:AC32) -> 4.5 | AF32: 236.64 | AG32: =+AF32-AF31 -> 4.99 | AH32: 215 | AI32: 235 | AJ32: NORMAL | AK32: 130.14833 | AL32: =+AK32-AK31 -> 5.172919 | AM32: 110 | AN32: 142 | AO32: NORMAL | AP32: 80.57 | AQ32: 73 | AR32: 84 | AS32: 13.28 | AT32: 12 | AU32: 17 | AY32: =+AY31+1 -> 45429 | AZ32: 12485870 | BA32: 11248059 | BB32: 9118039 | BC32: 4946801 | BD32: =+AZ32+BB32+BC32 -> 26550710 | BE32: =+BD32/1000 -> 26550.71 | BG32: 14 | BH32: 9 | BI32: =+AVERAGE(BG32:BH32) -> 11.5 | BL32: =+A32 -> 45794 | BR32: =+TEXT(BS32,"dddd") -> sábado | BS32: =+BL32 -> 45794 | BT32: =BM32/1000 -> 0 | BU32: =BN32*$CA$9/$CA$8/1000 -> 0 | BV32: =BO32*$CA$10/$CA$8/1000 -> 0 | BW32: =BP32*$CA$11/$CA$8/1000 -> 0 | BX32: =+BT32+BU32+BV32+BW32 -> 0 | CC32: =+BL32 -> 45794
A33: 45795 | B33: 118.8 | C33: 40.6 | D33: 31 | E33: 26.7 | F33: 7.8 | H33: 25.9 | I33: 10.5 | J33: 37 | K33: =SUM(H33:J33) -> 73.4 | M33: 2.6 | N33: 33.9 | O33: =SUM(M33:N33) -> 36.5 | Q33: 12.9 | R33: 0 | S33: 0 | T33: =SUM(Q33:S33) -> 12.9 | V33: 13 | W33: 21 | X33: =+AVERAGE(V33:W33) -> 17 | Y33: 11 | Z33: 19 | AA33: =+AVERAGE(Y33:Z33) -> 15 | AB33: 0 | AC33: 5 | AD33: =+AVERAGE(AB33:AC33) -> 2.5 | AF33: 239.15 | AG33: =+AF33-AF32 -> 2.51 | AH33: 215 | AI33: 235 | AJ33: NORMAL | AK33: 131.69871 | AL33: =+AK33-AK32 -> 1.55038 | AM33: 110 | AN33: 142 | AO33: NORMAL | AP33: 82.02 | AQ33: 73 | AR33: 84 | AS33: 13.58 | AT33: 12 | AU33: 17 | AY33: =+AY32+1 -> 45430 | AZ33: 10655545 | BA33: 12565189 | BB33: 12048240 | BC33: 4945950 | BD33: =+AZ33+BB33+BC33 -> 27649735 | BE33: =+BD33/1000 -> 27649.735 | BG33: 13 | BH33: 6 | BI33: =+AVERAGE(BG33:BH33) -> 9.5 | BL33: =+A33 -> 45795 | BR33: =+TEXT(BS33,"dddd") -> domingo | BS33: =+BL33 -> 45795 | BT33: =BM33/1000 -> 0 | BU33: =BN33*$CA$9/$CA$8/1000 -> 0 | BV33: =BO33*$CA$10/$CA$8/1000 -> 0 | BW33: =BP33*$CA$11/$CA$8/1000 -> 0 | BX33: =+BT33+BU33+BV33+BW33 -> 0 | CC33: =+BL33 -> 45795
A34: 45796 | B34: 141.5 | C34: 51.4 | D34: 34.7 | E34: 38.5 | F34: 6 | H34: 26.7 | I34: 10.5 | J34: 38.7 | K34: =SUM(H34:J34) -> 75.9 | M34: 2.6 | N34: 30.7 | O34: =SUM(M34:N34) -> 33.3 | Q34: 19.5 | R34: 0 | S34: 0 | T34: =SUM(Q34:S34) -> 19.5 | V34: 10 | W34: 20 | X34: =+AVERAGE(V34:W34) -> 15 | Y34: 9 | Z34: 15 | AA34: =+AVERAGE(Y34:Z34) -> 12 | AB34: -1 | AC34: 6 | AD34: =+AVERAGE(AB34:AC34) -> 2.5 | AF34: 229.94 | AG34: =+AF34-AF33 -> -9.21 | AH34: 215 | AI34: 235 | AJ34: NORMAL | AK34: 128.11145 | AL34: =+AK34-AK33 -> -3.58726 | AM34: 110 | AN34: 142 | AO34: NORMAL | AP34: 83.8 | AQ34: 73 | AR34: 84 | AS34: 15.82 | AT34: 12 | AU34: 17 | AY34: =+AY33+1 -> 45431 | AZ34: 10625840 | BA34: 13463135 | BB34: 12059349 | BC34: 4945883 | BD34: =+AZ34+BB34+BC34 -> 27631072 | BE34: =+BD34/1000 -> 27631.072 | BG34: 14 | BH34: 7 | BI34: =+AVERAGE(BG34:BH34) -> 10.5 | BL34: =+A34 -> 45796 | BR34: =+TEXT(BS34,"dddd") -> lunes | BS34: =+BL34 -> 45796 | BT34: =BM34/1000 -> 0 | BU34: =BN34*$CA$9/$CA$8/1000 -> 0 | BV34: =BO34*$CA$10/$CA$8/1000 -> 0 | BW34: =BP34*$CA$11/$CA$8/1000 -> 0 | BX34: =+BT34+BU34+BV34+BW34 -> 0 | CC34: =+BL34 -> 45796
A35: 45797 | B35: 147.6 | C35: 56.1 | D35: 35.1 | E35: 40.5 | F35: 3.4 | H35: 27.9 | I35: 10.4 | J35: 39.6 | K35: =SUM(H35:J35) -> 77.9 | M35: 2.6 | N35: 30.8 | O35: =SUM(M35:N35) -> 33.4 | Q35: 21.2 | R35: 0 | S35: 0 | T35: =SUM(Q35:S35) -> 21.2 | V35: 11 | W35: 18 | X35: =+AVERAGE(V35:W35) -> 14.5 | Y35: 7 | Z35: 17 | AA35: =+AVERAGE(Y35:Z35) -> 12 | AB35: 1 | AC35: 8 | AD35: =+AVERAGE(AB35:AC35) -> 4.5 | AF35: 219.7 | AG35: =+AF35-AF34 -> -10.24 | AH35: 215 | AI35: 235 | AJ35: NORMAL | AK35: 123.19908 | AL35: =+AK35-AK34 -> -4.91237 | AM35: 110 | AN35: 142 | AO35: NORMAL | AP35: 77.31 | AQ35: 73 | AR35: 84 | AS35: 14.27 | AT35: 12 | AU35: 17 | AY35: =+AY34+1 -> 45432 | AZ35: 10830387 | BA35: 13266089 | BB35: 9042348 | BC35: 4960079 | BD35: =+AZ35+BB35+BC35 -> 24832814 | BE35: =+BD35/1000 -> 24832.814 | BG35: 16 | BH35: 9 | BI35: =+AVERAGE(BG35:BH35) -> 12.5 | BL35: =+A35 -> 45797 | BR35: =+TEXT(BS35,"dddd") -> martes | BS35: =+BL35 -> 45797 | BT35: =BM35/1000 -> 0 | BU35: =BN35*$CA$9/$CA$8/1000 -> 0 | BV35: =BO35*$CA$10/$CA$8/1000 -> 0 | BW35: =BP35*$CA$11/$CA$8/1000 -> 0 | BX35: =+BT35+BU35+BV35+BW35 -> 0 | CC35: =+BL35 -> 45797
A36: 45798 | B36: 151.4 | C36: 58.9 | D36: 37.4 | E36: 39.8 | F36: 4.9 | H36: 27.9 | I36: 10.1 | J36: 42.7 | K36: =SUM(H36:J36) -> 80.7 | M36: 2.5 | N36: 31.6 | O36: =SUM(M36:N36) -> 34.1 | Q36: 20.5 | R36: 0 | S36: 7 | T36: =SUM(Q36:S36) -> 27.5 | V36: 14 | W36: 19 | X36: =+AVERAGE(V36:W36) -> 16.5 | Y36: 9 | Z36: 15 | AA36: =+AVERAGE(Y36:Z36) -> 12 | AB36: 1 | AC36: 8 | AD36: =+AVERAGE(AB36:AC36) -> 4.5 | AF36: 214.96 | AG36: =+AF36-AF35 -> -4.74 | AH36: 215 | AI36: 235 | AJ36: NORMAL | AK36: 118.86396 | AL36: =+AK36-AK35 -> -4.33512 | AM36: 110 | AN36: 142 | AO36: NORMAL | AP36: 72.86 | AQ36: 73 | AR36: 84 | AS36: 14.09 | AT36: 12 | AU36: 17 | AY36: =+AY35+1 -> 45433 | AZ36: 11998233 | BA36: 12942585 | BB36: 6017759 | BC36: 7284937 | BD36: =+AZ36+BB36+BC36 -> 25300929 | BE36: =+BD36/1000 -> 25300.929 | BG36: 15 | BH36: 12 | BI36: =+AVERAGE(BG36:BH36) -> 13.5 | BL36: =+A36 -> 45798 | BR36: =+TEXT(BS36,"dddd") -> miércoles | BS36: =+BL36 -> 45798 | BT36: =BM36/1000 -> 0 | BU36: =BN36*$CA$9/$CA$8/1000 -> 0 | BV36: =BO36*$CA$10/$CA$8/1000 -> 0 | BW36: =BP36*$CA$11/$CA$8/1000 -> 0 | BX36: =+BT36+BU36+BV36+BW36 -> 0 | CC36: =+BL36 -> 45798
A37: 45799 | B37: 150 | C37: 58.8 | D37: 37.3 | E37: 36.5 | F37: 5.8 | H37: 27.1 | I37: 10.3 | J37: 42.6 | K37: =SUM(H37:J37) -> 80 | M37: 2.5 | N37: 33.1 | O37: =SUM(M37:N37) -> 35.6 | Q37: 18.7 | R37: 0 | S37: 10 | T37: =SUM(Q37:S37) -> 28.7 | V37: 15 | W37: 18 | X37: =+AVERAGE(V37:W37) -> 16.5 | Y37: 7 | Z37: 15 | AA37: =+AVERAGE(Y37:Z37) -> 11 | AB37: -2 | AC37: 8 | AD37: =+AVERAGE(AB37:AC37) -> 3 | AF37: 212.63 | AG37: =+AF37-AF36 -> -2.33 | AH37: 215 | AI37: 235 | AJ37: NORMAL | AK37: 115.32206 | AL37: =+AK37-AK36 -> -3.5419 | AM37: 110 | AN37: 142 | AO37: NORMAL | AP37: 73.6 | AQ37: 73 | AR37: 84 | AS37: 13.98 | AT37: 12 | AU37: 17 | AY37: =+AY36+1 -> 45434 | AZ37: 12112345 | BA37: 12742426 | BB37: 6025490 | BC37: 7434278 | BD37: =+AZ37+BB37+BC37 -> 25572113 | BE37: =+BD37/1000 -> 25572.113 | BG37: 14 | BH37: 12 | BI37: =+AVERAGE(BG37:BH37) -> 13 | BL37: =+A37 -> 45799 | BR37: =+TEXT(BS37,"dddd") -> jueves | BS37: =+BL37 -> 45799 | BT37: =BM37/1000 -> 0 | BU37: =BN37*$CA$9/$CA$8/1000 -> 0 | BV37: =BO37*$CA$10/$CA$8/1000 -> 0 | BW37: =BP37*$CA$11/$CA$8/1000 -> 0 | BX37: =+BT37+BU37+BV37+BW37 -> 0 | CC37: =+BL37 -> 45799
A38: 45800 | B38: 146 | C38: 57 | D38: 36.4 | E38: 32.5 | F38: 6.5 | H38: 27.8 | I38: 10 | J38: 42.7 | K38: =SUM(H38:J38) -> 80.5 | M38: 2.5 | N38: 34.6 | O38: =SUM(M38:N38) -> 37.1 | Q38: 19.2 | R38: 0 | S38: 12 | T38: =SUM(Q38:S38) -> 31.2 | V38: 14 | W38: 17 | X38: =+AVERAGE(V38:W38) -> 15.5 | Y38: 11 | Z38: 16 | AA38: =+AVERAGE(Y38:Z38) -> 13.5 | AB38: 1 | AC38: 8 | AD38: =+AVERAGE(AB38:AC38) -> 4.5 | AF38: 214.32859 | AG38: =+AF38-AF37 -> 1.698591 | AH38: 215 | AI38: 235 | AJ38: NORMAL | AK38: 116.45427 | AL38: =+AK38-AK37 -> 1.13221 | AM38: 110 | AN38: 142 | AO38: NORMAL | AP38: 72.33 | AQ38: 73 | AR38: 84 | AS38: 12.99 | AT38: 12 | AU38: 17 | AY38: =+AY37+1 -> 45435 | AZ38: 13005318 | BA38: 13401784 | BB38: 6024381 | BC38: 6596522 | BD38: =+AZ38+BB38+BC38 -> 25626221 | BE38: =+BD38/1000 -> 25626.221 | BG38: 15 | BH38: 12 | BI38: =+AVERAGE(BG38:BH38) -> 13.5 | BL38: =+A38 -> 45800 | BR38: =+TEXT(BS38,"dddd") -> viernes | BS38: =+BL38 -> 45800 | BT38: =BM38/1000 -> 0 | BU38: =BN38*$CA$9/$CA$8/1000 -> 0 | BV38: =BO38*$CA$10/$CA$8/1000 -> 0 | BW38: =BP38*$CA$11/$CA$8/1000 -> 0 | BX38: =+BT38+BU38+BV38+BW38 -> 0 | CC38: =+BL38 -> 45800
A39: 45801 | B39: 131.1 | C39: 50.6 | D39: 33.7 | E39: 28.8 | F39: 6.9 | H39: 24.9 | I39: 9.2 | J39: 42.2 | K39: =SUM(H39:J39) -> 76.3 | M39: 2.4 | N39: 34.9 | O39: =SUM(M39:N39) -> 37.3 | Q39: 19 | R39: 0 | S39: 8 | T39: =SUM(Q39:S39) -> 27 | V39: 14 | W39: 20 | X39: =+AVERAGE(V39:W39) -> 17 | Y39: 11 | Z39: 15 | AA39: =+AVERAGE(Y39:Z39) -> 13 | AB39: 2 | AC39: 8 | AD39: =+AVERAGE(AB39:AC39) -> 5 | AF39: 220.27846 | AG39: =+AF39-AF38 -> 5.949867 | AH39: 215 | AI39: 235 | AJ39: NORMAL | AK39: 120.00277 | AL39: =+AK39-AK38 -> 3.5485 | AM39: 110 | AN39: 142 | AO39: NORMAL | AP39: 72.14 | AQ39: 73 | AR39: 84 | AS39: 12.79 | AT39: 12 | AU39: 17 | AY39: =+AY38+1 -> 45436 | AZ39: 12058018 | BA39: 12551102 | BB39: 14045461 | BC39: 6978626 | BD39: =+AZ39+BB39+BC39 -> 33082105 | BE39: =+BD39/1000 -> 33082.105 | BG39: 13 | BH39: 7 | BI39: =+AVERAGE(BG39:BH39) -> 10 | BL39: =+A39 -> 45801 | BR39: =+TEXT(BS39,"dddd") -> sábado | BS39: =+BL39 -> 45801 | BT39: =BM39/1000 -> 0 | BU39: =BN39*$CA$9/$CA$8/1000 -> 0 | BV39: =BO39*$CA$10/$CA$8/1000 -> 0 | BW39: =BP39*$CA$11/$CA$8/1000 -> 0 | BX39: =+BT39+BU39+BV39+BW39 -> 0 | CC39: =+BL39 -> 45801
A40: 45802 | B40: 128.7 | C40: 47.6 | D40: 32 | E40: 27.8 | F40: 6.9 | H40: 27.3 | I40: 10.3 | J40: 41.5 | K40: =SUM(H40:J40) -> 79.1 | M40: 2.4 | N40: 36 | O40: =SUM(M40:N40) -> 38.4 | Q40: 18.9 | R40: 0 | S40: 3.5 | T40: =SUM(Q40:S40) -> 22.4 | V40: 15 | W40: 18 | X40: =+AVERAGE(V40:W40) -> 16.5 | Y40: 10 | Z40: 18 | AA40: =+AVERAGE(Y40:Z40) -> 14 | AB40: 3 | AC40: 11 | AD40: =+AVERAGE(AB40:AC40) -> 7 | AF40: 227.52 | AG40: =+AF40-AF39 -> 7.241542 | AH40: 215 | AI40: 235 | AJ40: NORMAL | AK40: 124.06767 | AL40: =+AK40-AK39 -> 4.0649 | AM40: 110 | AN40: 142 | AO40: NORMAL | AP40: 76.22 | AQ40: 73 | AR40: 84 | AS40: 13.12 | AT40: 12 | AU40: 17 | AY40: =+AY39+1 -> 45437 | AZ40: 13032172 | BA40: 12346967 | BB40: 15554452 | BC40: 5736124 | BD40: =+AZ40+BB40+BC40 -> 34322748 | BE40: =+BD40/1000 -> 34322.748 | BG40: 11 | BH40: 4 | BI40: =+AVERAGE(BG40:BH40) -> 7.5 | BL40: =+A40 -> 45802 | BR40: =+TEXT(BS40,"dddd") -> domingo | BS40: =+BL40 -> 45802 | BT40: =BM40/1000 -> 0 | BU40: =BN40*$CA$9/$CA$8/1000 -> 0 | BV40: =BO40*$CA$10/$CA$8/1000 -> 0 | BW40: =BP40*$CA$11/$CA$8/1000 -> 0 | BX40: =+BT40+BU40+BV40+BW40 -> 0 | CC40: =+BL40 -> 45802
...

Sheet Conv. valores
AA1: Tramos finales | AG1: BUENOS AIRES | AJ1: ESQUEL | AM1: CAMMESA
B2: FECHA | C2: Demanda Total DS | D2: Prioritaria | E2: Industria | F2: Usinas | G2: Exportaciones | H2: TGS | I2: TGN | J2: Iny. Enarsa | K2: GPM | L2: Bolivia | M2: ESCOBAR | N2: Iny. Total | O2: Linepack TGS | P2: Var. Linepack TGS | Q2: Límite Inf. | R2: Límite Sup. | S2: Linepack TGN | T2: Var. Linepack TGN | U2: Límite Inf. | V2: Límite Sup. | W2: Linepack Total | X2: Variación Total | Y2: Límite Inf. | Z2: Límite Sup. | AA2: TGS | AB2: Límite Inf. | AC2: Límite Sup. | AD2: TGN | AE2: Límite Inf. | AF2: Límite Sup. | AG2: Temp. Min | AH2: Temp. Max | AI2: Temp Promedio | AJ2: Temp. Min | AK2: Temp. Max | AL2: Temp Promedio | AM2: GAS | AN2: GAS OIL | AO2: FUEL OIL | AP2: CARBON | AQ2: TOTAL
B3: 46111 | AM3: =+VLOOKUP($B3,Datos!$A$6:$BX$2600,72) -> 53.827 | AN3: =+VLOOKUP($B3,Datos!$A$6:$BX$2600,73) -> 8.2347571 | AO3: =+VLOOKUP($B3,Datos!$A$6:$BX$2600,74) -> 1.3101667 | AP3: =+VLOOKUP($B3,Datos!$A$6:$BX$2600,75) -> 0 | AQ3: =+SUM(AM3:AP3) -> 63.371924
B4: =+B3+1 -> 46112 | AM4: =+VLOOKUP($B4,Datos!$A$6:$BX$2600,72) -> 55.31 | AN4: =+VLOOKUP($B4,Datos!$A$6:$BX$2600,73) -> 13.886321 | AO4: =+VLOOKUP($B4,Datos!$A$6:$BX$2600,74) -> 1.1818333 | AP4: =+VLOOKUP($B4,Datos!$A$6:$BX$2600,75) -> 1.053 | AQ4: =+SUM(AM4:AP4) -> 71.431155
B5: =+B4+1 -> 46113 | C5: =+VLOOKUP($B5,Datos!$A$5:$F$3600,2) -> 131.6 | D5: =+VLOOKUP($B5,Datos!$A$5:$F$3600,3) -> 18.5 | E5: =+VLOOKUP($B5,Datos!$A$5:$F$3600,4) -> 36.7 | F5: =+VLOOKUP($B5,Datos!$A$5:$F$3600,5) -> 54.4 | G5: =+VLOOKUP($B5,Datos!$A$5:$F$3600,6) -> 11 | H5: =+VLOOKUP($B5,Datos!$A$5:$T$3600,11) -> 69.3 | I5: =+VLOOKUP($B5,Datos!$A$5:$T$3600,15) -> 34.3 | J5: =+VLOOKUP($B5,Datos!$A$5:$T$3600,20) -> 22.8 | K5: =+VLOOKUP($B5,Datos!$A$5:$T$3600,17) -> 20.9 | L5: =+VLOOKUP($B5,Datos!$A$5:$T$3600,18) -> 1.9 | M5: =+VLOOKUP($B5,Datos!$A$5:$T$3600,19) -> 0 | N5: =+SUM(H5:J5) -> 126.4 | O5: =+VLOOKUP($B5,Datos!$A$5:$AO$3600,32) -> 217.8 | Q5: =+VLOOKUP($B5,Datos!$A$5:$AO$3600,34) -> 215 | R5: =+VLOOKUP($B5,Datos!$A$5:$AO$3600,35) -> 235 | S5: =+VLOOKUP($B5,Datos!$A$5:$AO$3600,37) -> 124.88823 | U5: =+VLOOKUP($B5,Datos!$A$5:$AO$3600,39) -> 110 | V5: =+VLOOKUP($B5,Datos!$A$5:$AO$3600,40) -> 142 | W5: =+O5+S5 -> 342.68823 | Y5: =+Q5+U5 -> 325 | Z5: =+R5+V5 -> 377 | AA5: =+VLOOKUP($B5,Datos!$A$5:$AU$3600,42) -> 0 | AB5: =+VLOOKUP($B5,Datos!$A$5:$AU$360,43) -> 0 | AC5: =+VLOOKUP($B5,Datos!$A$5:$AU$360,44) -> 0 | AD5: =+VLOOKUP($B5,Datos!$A$5:$AU$360,45) -> 0 | AE5: =+VLOOKUP($B5,Datos!$A$5:$AU$360,46) -> 0 | AF5: =+VLOOKUP($B5,Datos!$A$5:$AU$360,47) -> 0 | AG5: =+VLOOKUP($B5,Datos!$A$5:$AU$3600,25) -> 21 | AH5: =+VLOOKUP($B5,Datos!$A$5:$AU$3600,26) -> 28 | AI5: =+VLOOKUP($B5,Datos!$A$5:$AU$3600,27) -> 24.5 | AJ5: =+VLOOKUP($B5,Datos!$A$5:$AU$3600,28) -> 0 | AK5: =+VLOOKUP($B5,Datos!$A$5:$AU$3600,29) -> 13 | AL5: =+VLOOKUP($B5,Datos!$A$5:$AU$3600,30) -> 6.5 | AM5: =+VLOOKUP($B5,Datos!$A$6:$BX$2600,72) -> 58.685 | AN5: =+VLOOKUP($B5,Datos!$A$6:$BX$2600,73) -> 10.513564 | AO5: =+VLOOKUP($B5,Datos!$A$6:$BX$2600,74) -> 0.8015 | AP5: =+VLOOKUP($B5,Datos!$A$6:$BX$2600,75) -> 1.7993571 | AQ5: =+SUM(AM5:AP5) -> 71.799421
B6: =+B5+1 -> 46114 | C6: =+VLOOKUP($B6,Datos!$A$5:$F$3600,2) -> 122.3 | D6: =+VLOOKUP($B6,Datos!$A$5:$F$3600,3) -> 18 | E6: =+VLOOKUP($B6,Datos!$A$5:$F$3600,4) -> 36.5 | F6: =+VLOOKUP($B6,Datos!$A$5:$F$3600,5) -> 49.5 | G6: =+VLOOKUP($B6,Datos!$A$5:$F$3600,6) -> 11.4 | H6: =+VLOOKUP($B6,Datos!$A$5:$T$3600,11) -> 67.4 | I6: =+VLOOKUP($B6,Datos!$A$5:$T$3600,15) -> 34 | J6: =+VLOOKUP($B6,Datos!$A$5:$T$3600,20) -> 19.5 | K6: =+VLOOKUP($B6,Datos!$A$5:$T$3600,17) -> 19.5 | L6: =+VLOOKUP($B6,Datos!$A$5:$T$3600,18) -> 0 | M6: =+VLOOKUP($B6,Datos!$A$5:$T$3600,19) -> 0 | N6: =+SUM(H6:J6) -> 120.9 | O6: =+VLOOKUP($B6,Datos!$A$5:$AO$3600,32) -> 216.66 | Q6: =+VLOOKUP($B6,Datos!$A$5:$AO$3600,34) -> 215 | R6: =+VLOOKUP($B6,Datos!$A$5:$AO$3600,35) -> 235 | S6: =+VLOOKUP($B6,Datos!$A$5:$AO$3600,37) -> 126.03956 | U6: =+VLOOKUP($B6,Datos!$A$5:$AO$3600,39) -> 110 | V6: =+VLOOKUP($B6,Datos!$A$5:$AO$3600,40) -> 142 | W6: =+O6+S6 -> 342.69956 | Y6: =+Q6+U6 -> 325 | Z6: =+R6+V6 -> 377 | AA6: =+VLOOKUP($B6,Datos!$A$5:$AU$3600,42) -> 0 | AB6: =+VLOOKUP($B6,Datos!$A$5:$AU$3600,43) -> 0 | AC6: =+VLOOKUP($B6,Datos!$A$5:$AU$3600,44) -> 0 | AD6: =+VLOOKUP($B6,Datos!$A$5:$AU$3600,45) -> 0 | AE6: =+VLOOKUP($B6,Datos!$A$5:$AU$3600,46) -> 0 | AF6: =+VLOOKUP($B6,Datos!$A$5:$AU$3600,47) -> 0 | AG6: =+VLOOKUP($B6,Datos!$A$5:$AU$3600,25) -> 20 | AH6: =+VLOOKUP($B6,Datos!$A$5:$AU$3600,26) -> 26 | AI6: =+VLOOKUP($B6,Datos!$A$5:$AU$3600,27) -> 23 | AJ6: =+VLOOKUP($B6,Datos!$A$5:$AU$3600,28) -> 0 | AK6: =+VLOOKUP($B6,Datos!$A$5:$AU$3600,29) -> 15 | AL6: =+VLOOKUP($B6,Datos!$A$5:$AU$3600,30) -> 7.5 | AM6: =+VLOOKUP($B6,Datos!$A$6:$BX$2600,72) -> 58.022 | AN6: =+VLOOKUP($B6,Datos!$A$6:$BX$2600,73) -> 0.10929286 | AO6: =+VLOOKUP($B6,Datos!$A$6:$BX$2600,74) -> 0 | AP6: =+VLOOKUP($B6,Datos!$A$6:$BX$2600,75) -> 1.7556429 | AQ6: =+SUM(AM6:AP6) -> 59.886936
B7: =+B6+1 -> 46115 | C7: =+VLOOKUP($B7,Datos!$A$5:$F$3600,2) -> 116.8 | D7: =+VLOOKUP($B7,Datos!$A$5:$F$3600,3) -> 18.1 | E7: =+VLOOKUP($B7,Datos!$A$5:$F$3600,4) -> 34.9 | F7: =+VLOOKUP($B7,Datos!$A$5:$F$3600,5) -> 44.8 | G7: =+VLOOKUP($B7,Datos!$A$5:$F$3600,6) -> 10.8 | H7: =+VLOOKUP($B7,Datos!$A$5:$T$3600,11) -> 65.9 | I7: =+VLOOKUP($B7,Datos!$A$5:$T$3600,15) -> 32.1 | J7: =+VLOOKUP($B7,Datos!$A$5:$T$3600,20) -> 19.1 | K7: =+VLOOKUP($B7,Datos!$A$5:$T$3600,17) -> 19.1 | L7: =+VLOOKUP($B7,Datos!$A$5:$T$3600,18) -> 0 | M7: =+VLOOKUP($B7,Datos!$A$5:$T$3600,19) -> 0 | N7: =+SUM(H7:J7) -> 117.1 | O7: =+VLOOKUP($B7,Datos!$A$5:$AO$3600,32) -> 215.09 | Q7: =+VLOOKUP($B7,Datos!$A$5:$AO$3600,34) -> 215 | R7: =+VLOOKUP($B7,Datos!$A$5:$AO$3600,35) -> 235 | S7: =+VLOOKUP($B7,Datos!$A$5:$AO$3600,37) -> 129.31785 | U7: =+VLOOKUP($B7,Datos!$A$5:$AO$3600,39) -> 110 | V7: =+VLOOKUP($B7,Datos!$A$5:$AO$3600,40) -> 142 | W7: =+O7+S7 -> 344.40785 | Y7: =+Q7+U7 -> 325 | Z7: =+R7+V7 -> 377 | AA7: =+VLOOKUP($B7,Datos!$A$5:$AU$3600,42) -> 0 | AB7: =+VLOOKUP($B7,Datos!$A$5:$AU$3600,43) -> 0 | AC7: =+VLOOKUP($B7,Datos!$A$5:$AU$3600,44) -> 0 | AD7: =+VLOOKUP($B7,Datos!$A$5:$AU$3600,45) -> 0 | AE7: =+VLOOKUP($B7,Datos!$A$5:$AU$3600,46) -> 0 | AF7: =+VLOOKUP($B7,Datos!$A$5:$AU$3600,47) -> 0 | AG7: =+VLOOKUP($B7,Datos!$A$5:$AU$3600,25) -> 19 | AH7: =+VLOOKUP($B7,Datos!$A$5:$AU$3600,26) -> 29 | AI7: =+VLOOKUP($B7,Datos!$A$5:$AU$3600,27) -> 24 | AJ7: =+VLOOKUP($B7,Datos!$A$5:$AU$3600,28) -> 3 | AK7: =+VLOOKUP($B7,Datos!$A$5:$AU$3600,29) -> 13 | AL7: =+VLOOKUP($B7,Datos!$A$5:$AU$3600,30) -> 8 | AM7: =+VLOOKUP($B7,Datos!$A$6:$BX$2600,72) -> 50.214 | AN7: =+VLOOKUP($B7,Datos!$A$6:$BX$2600,73) -> 0.1287 | AO7: =+VLOOKUP($B7,Datos!$A$6:$BX$2600,74) -> 0 | AP7: =+VLOOKUP($B7,Datos!$A$6:$BX$2600,75) -> 1.8115714 | AQ7: =+SUM(AM7:AP7) -> 52.154271
B8: =+B7+1 -> 46116 | C8: =+VLOOKUP($B8,Datos!$A$5:$F$3600,2) -> 111.3 | D8: =+VLOOKUP($B8,Datos!$A$5:$F$3600,3) -> 21.6 | E8: =+VLOOKUP($B8,Datos!$A$5:$F$3600,4) -> 34.7 | F8: =+VLOOKUP($B8,Datos!$A$5:$F$3600,5) -> 36.1 | G8: =+VLOOKUP($B8,Datos!$A$5:$F$3600,6) -> 8.5 | H8: =+VLOOKUP($B8,Datos!$A$5:$T$3600,11) -> 65.3 | I8: =+VLOOKUP($B8,Datos!$A$5:$T$3600,15) -> 32.6 | J8: =+VLOOKUP($B8,Datos!$A$5:$T$3600,20) -> 20.1 | K8: =+VLOOKUP($B8,Datos!$A$5:$T$3600,17) -> 20.1 | L8: =+VLOOKUP($B8,Datos!$A$5:$T$3600,18) -> 0 | M8: =+VLOOKUP($B8,Datos!$A$5:$T$3600,19) -> 0 | N8: =+SUM(H8:J8) -> 118 | O8: =+VLOOKUP($B8,Datos!$A$5:$AO$3600,32) -> 220.23 | Q8: =+VLOOKUP($B8,Datos!$A$5:$AO$3600,34) -> 215 | R8: =+VLOOKUP($B8,Datos!$A$5:$AO$3600,35) -> 235 | S8: =+VLOOKUP($B8,Datos!$A$5:$AO$3600,37) -> 132.93943 | U8: =+VLOOKUP($B8,Datos!$A$5:$AO$3600,39) -> 110 | V8: =+VLOOKUP($B8,Datos!$A$5:$AO$3600,40) -> 142 | W8: =+O8+S8 -> 353.16943 | Y8: =+Q8+U8 -> 325 | Z8: =+R8+V8 -> 377 | AA8: =+VLOOKUP($B8,Datos!$A$5:$AU$3600,42) -> 0 | AB8: =+VLOOKUP($B8,Datos!$A$5:$AU$3600,43) -> 0 | AC8: =+VLOOKUP($B8,Datos!$A$5:$AU$3600,44) -> 0 | AD8: =+VLOOKUP($B8,Datos!$A$5:$AU$3600,45) -> 0 | AE8: =+VLOOKUP($B8,Datos!$A$5:$AU$3600,46) -> 0 | AF8: =+VLOOKUP($B8,Datos!$A$5:$AU$3600,47) -> 0 | AG8: =+VLOOKUP($B8,Datos!$A$5:$AU$3600,25) -> 14 | AH8: =+VLOOKUP($B8,Datos!$A$5:$AU$3600,26) -> 19 | AI8: =+VLOOKUP($B8,Datos!$A$5:$AU$3600,27) -> 16.5 | AJ8: =+VLOOKUP($B8,Datos!$A$5:$AU$3600,28) -> 0 | AK8: =+VLOOKUP($B8,Datos!$A$5:$AU$3600,29) -> 17 | AL8: =+VLOOKUP($B8,Datos!$A$5:$AU$3600,30) -> 8.5 | AM8: =+VLOOKUP($B8,Datos!$A$6:$BX$2600,72) -> 42.328 | AN8: =+VLOOKUP($B8,Datos!$A$6:$BX$2600,73) -> 0.11746429 | AO8: =+VLOOKUP($B8,Datos!$A$6:$BX$2600,74) -> 0.0058333333 | AP8: =+VLOOKUP($B8,Datos!$A$6:$BX$2600,75) -> 1.9028571 | AQ8: =+SUM(AM8:AP8) -> 44.354155
B9: =+B8+1 -> 46117 | C9: =+VLOOKUP($B9,Datos!$A$5:$F$3600,2) -> 105.8 | D9: =+VLOOKUP($B9,Datos!$A$5:$F$3600,3) -> 23.8 | E9: =+VLOOKUP($B9,Datos!$A$5:$F$3600,4) -> 33.5 | F9: =+VLOOKUP($B9,Datos!$A$5:$F$3600,5) -> 29 | G9: =+VLOOKUP($B9,Datos!$A$5:$F$3600,6) -> 8.9 | H9: =+VLOOKUP($B9,Datos!$A$5:$T$3600,11) -> 52.7 | I9: =+VLOOKUP($B9,Datos!$A$5:$T$3600,15) -> 33.2 | J9: =+VLOOKUP($B9,Datos!$A$5:$T$3600,20) -> 20.2 | K9: =+VLOOKUP($B9,Datos!$A$5:$T$3600,17) -> 20.2 | L9: =+VLOOKUP($B9,Datos!$A$5:$T$3600,18) -> 0 | M9: =+VLOOKUP($B9,Datos!$A$5:$T$3600,19) -> 0 | N9: =+SUM(H9:J9) -> 106.1 | O9: =+VLOOKUP($B9,Datos!$A$5:$AO$3600,32) -> 220.85 | P9: =+O9-O8 -> 0.62 | Q9: =+VLOOKUP($B9,Datos!$A$5:$AO$3600,34) -> 215 | R9: =+VLOOKUP($B9,Datos!$A$5:$AO$3600,35) -> 235 | S9: =+VLOOKUP($B9,Datos!$A$5:$AO$3600,37) -> 134.44768 | T9: =+S9-S8 -> 1.50825 | U9: =+VLOOKUP($B9,Datos!$A$5:$AO$3600,39) -> 110 | V9: =+VLOOKUP($B9,Datos!$A$5:$AO$3600,40) -> 142 | W9: =+O9+S9 -> 355.29768 | X9: =+W9-W8 -> 2.12825 | Y9: =+Q9+U9 -> 325 | Z9: =+R9+V9 -> 377 | AA9: =+VLOOKUP($B9,Datos!$A$5:$AU$3600,42) -> 0 | AB9: =+VLOOKUP($B9,Datos!$A$5:$AU$3600,43) -> 0 | AC9: =+VLOOKUP($B9,Datos!$A$5:$AU$3600,44) -> 0 | AD9: =+VLOOKUP($B9,Datos!$A$5:$AU$3600,45) -> 0 | AE9: =+VLOOKUP($B9,Datos!$A$5:$AU$3600,46) -> 0 | AF9: =+VLOOKUP($B9,Datos!$A$5:$AU$3600,47) -> 0 | AG9: =+VLOOKUP($B9,Datos!$A$5:$AU$3600,25) -> 12 | AH9: =+VLOOKUP($B9,Datos!$A$5:$AU$3600,26) -> 19 | AI9: =+VLOOKUP($B9,Datos!$A$5:$AU$3600,27) -> 15.5 | AJ9: =+VLOOKUP($B9,Datos!$A$5:$AU$3600,28) -> 4 | AK9: =+VLOOKUP($B9,Datos!$A$5:$AU$3600,29) -> 17 | AL9: =+VLOOKUP($B9,Datos!$A$5:$AU$3600,30) -> 10.5 | AM9: =+VLOOKUP($B9,Datos!$A$6:$BX$2600,72) -> 33.26 | AN9: =+VLOOKUP($B9,Datos!$A$6:$BX$2600,73) -> 0.068435714 | AO9: =+VLOOKUP($B9,Datos!$A$6:$BX$2600,74) -> 0 | AP9: =+VLOOKUP($B9,Datos!$A$6:$BX$2600,75) -> 2.0211429 | AQ9: =+SUM(AM9:AP9) -> 35.349579
B10: =+B9+1 -> 46118 | C10: =+VLOOKUP($B10,Datos!$A$5:$F$3600,2) -> 120.3 | D10: =+VLOOKUP($B10,Datos!$A$5:$F$3600,3) -> 28.2 | E10: =+VLOOKUP($B10,Datos!$A$5:$F$3600,4) -> 37.2 | F10: =+VLOOKUP($B10,Datos!$A$5:$F$3600,5) -> 37.3 | G10: =+VLOOKUP($B10,Datos!$A$5:$F$3600,6) -> 10.9 | H10: =+VLOOKUP($B10,Datos!$A$5:$T$3600,11) -> 66.8 | I10: =+VLOOKUP($B10,Datos!$A$5:$T$3600,15) -> 32 | J10: =+VLOOKUP($B10,Datos!$A$5:$T$3600,20) -> 20.2 | K10: =+VLOOKUP($B10,Datos!$A$5:$T$3600,17) -> 20.2 | L10: =+VLOOKUP($B10,Datos!$A$5:$T$3600,18) -> 0 | M10: =+VLOOKUP($B10,Datos!$A$5:$T$3600,19) -> 0 | N10: =+SUM(H10:J10) -> 119 | O10: =+VLOOKUP($B10,Datos!$A$5:$AO$3600,32) -> 225.25 | P10: =+O10-O9 -> 4.4 | Q10: =+VLOOKUP($B10,Datos!$A$5:$AO$3600,34) -> 215 | R10: =+VLOOKUP($B10,Datos!$A$5:$AO$3600,35) -> 235 | S10: =+VLOOKUP($B10,Datos!$A$5:$AO$3600,37) -> 130.11544 | T10: =+S10-S9 -> -4.332237 | U10: =+VLOOKUP($B10,Datos!$A$5:$AO$3600,39) -> 110 | V10: =+VLOOKUP($B10,Datos!$A$5:$AO$3600,40) -> 142 | W10: =+O10+S10 -> 355.36544 | X10: =+W10-W9 -> 0.067763 | Y10: =+Q10+U10 -> 325 | Z10: =+R10+V10 -> 377 | AA10: =+VLOOKUP($B10,Datos!$A$5:$AU$3600,42) -> 0 | AB10: =+VLOOKUP($B10,Datos!$A$5:$AU$3600,43) -> 0 | AC10: =+VLOOKUP($B10,Datos!$A$5:$AU$3600,44) -> 0 | AD10: =+VLOOKUP($B10,Datos!$A$5:$AU$3600,45) -> 0 | AE10: =+VLOOKUP($B10,Datos!$A$5:$AU$3600,46) -> 0 | AF10: =+VLOOKUP($B10,Datos!$A$5:$AU$3600,47) -> 0 | AG10: =+VLOOKUP($B10,Datos!$A$5:$AU$3600,25) -> 15 | AH10: =+VLOOKUP($B10,Datos!$A$5:$AU$3600,26) -> 17 | AI10: =+VLOOKUP($B10,Datos!$A$5:$AU$3600,27) -> 16 | AJ10: =+VLOOKUP($B10,Datos!$A$5:$AU$3600,28) -> 1 | AK10: =+VLOOKUP($B10,Datos!$A$5:$AU$3600,29) -> 17 | AL10: =+VLOOKUP($B10,Datos!$A$5:$AU$3600,30) -> 9 | AM10: =+VLOOKUP($B10,Datos!$A$6:$BX$2600,72) -> 41.063 | AN10: =+VLOOKUP($B10,Datos!$A$6:$BX$2600,73) -> 0.38814286 | AO10: =+VLOOKUP($B10,Datos!$A$6:$BX$2600,74) -> 0 | AP10: =+VLOOKUP($B10,Datos!$A$6:$BX$2600,75) -> 1.917 | AQ10: =+SUM(AM10:AP10) -> 43.368143
